<sdf version='1.7'>
  <world name='default'>
    <light name='sun' type='directional'>
      <cast_shadows>1</cast_shadows>
      <pose>0 0 10 0 -0 0</pose>
      <diffuse>0.8 0.8 0.8 1</diffuse>
      <specular>0.2 0.2 0.2 1</specular>
      <attenuation>
        <range>1000</range>
        <constant>0.9</constant>
        <linear>0.01</linear>
        <quadratic>0.001</quadratic>
      </attenuation>
      <direction>-0.5 0.1 -0.9</direction>
      <spot>
        <inner_angle>0</inner_angle>
        <outer_angle>0</outer_angle>
        <falloff>0</falloff>
      </spot>
    </light>
    <physics name='default_physics' default='0' type='ode'>
      <real_time_update_rate>1000</real_time_update_rate>
      <max_step_size>0.001</max_step_size>
      <real_time_factor>1</real_time_factor>
      <ode>
        <solver>
          <type>quick</type>
          <iters>150</iters>
          <precon_iters>0</precon_iters>
          <sor>1.4</sor>
          <use_dynamic_moi_rescaling>1</use_dynamic_moi_rescaling>
        </solver>
        <constraints>
          <cfm>1e-05</cfm>
          <erp>0.2</erp>
          <contact_max_correcting_vel>2000</contact_max_correcting_vel>
          <contact_surface_layer>0.01</contact_surface_layer>
        </constraints>
      </ode>
    </physics>
    <scene>
      <ambient>0.4 0.4 0.4 1</ambient>
      <background>0.7 0.7 0.7 1</background>
      <shadows>1</shadows>
    </scene>
    <gui fullscreen='0'>
      <camera name='user_camera'>
        <pose>0.346489 -13.9175 11.7581 0 0.693799 1.60481</pose>
        <view_controller>orbit</view_controller>
        <projection_type>perspective</projection_type>
      </camera>
    </gui>
    <gravity>0 0 -9.8</gravity>
    <magnetic_field>6e-06 2.3e-05 -4.2e-05</magnetic_field>
    <atmosphere type='adiabatic'/>
    <audio>
      <device>default</device>
    </audio>
    <wind/>
    <spherical_coordinates>
      <surface_model>EARTH_WGS84</surface_model>
      <latitude_deg>0</latitude_deg>
      <longitude_deg>0</longitude_deg>
      <elevation>0</elevation>
      <heading_deg>0</heading_deg>
    </spherical_coordinates>
    <model name='fnr2022_map'>
      <static>1</static>
      <link name='link'>
        <collision name='collision'>
          <geometry>
            <plane>
              <normal>0 0 1</normal>
              <size>29.9 22</size>
            </plane>
          </geometry>
          <surface>
            <friction>
              <ode>
                <mu>100</mu>
                <mu2>50</mu2>
              </ode>
              <torsional>
                <ode/>
              </torsional>
            </friction>
            <contact>
              <ode/>
            </contact>
            <bounce/>
          </surface>
          <max_contacts>10</max_contacts>
        </collision>
        <visual name='visual'>
          <cast_shadows>0</cast_shadows>
          <geometry>
            <plane>
              <normal>0 0 1</normal>
              <size>29.9 22</size>
            </plane>
          </geometry>
          <material>
            <script>
              <uri>model://FNR2022_map/materials/scripts</uri>
              <uri>model://FNR2022_map/materials/textures</uri>
              <name>FNR2022/Image</name>
            </script>
          </material>
        </visual>
        <self_collide>0</self_collide>
        <enable_wind>0</enable_wind>
        <kinematic>0</kinematic>
      </link>
      <pose>-0.033622 1.43805 0 0 -0 0</pose>
    </model>
    <model name='semaphore_monitor'>
      <static>1</static>
      <pose>0 -0.044776 0.113553 0 0 -1.57185</pose>
      <link name='lcd1'>
        <pose>-0.4 0 1.0856 2.0071 -0 3.1415</pose>
        <collision name='collision1'>
          <geometry>
            <box>
              <size>0.4758 0.35685 0.01</size>
            </box>
          </geometry>
          <max_contacts>10</max_contacts>
          <surface>
            <bounce/>
            <friction>
              <ode/>
              <torsional>
                <ode/>
              </torsional>
            </friction>
            <contact>
              <ode/>
            </contact>
          </surface>
        </collision>
        <visual name='visual1'>
          <geometry>
            <box>
              <size>0.4758 0.35685 0.01</size>
            </box>
          </geometry>
          <material>
            <ambient>0.69 0.69 0.69 1</ambient>
            <diffuse>0.69 0.69 0.69 1</diffuse>
            <specular>0.1 0.1 0.1 1</specular>
            <emissive>0 0 0 0</emissive>
          </material>
          <plugin name='display_video_controller1' filename='libgazebo_ros_video.so'>
            <robotNamespace>monitor1</robotNamespace>
            <topicName>image1</topicName>
            <height>120</height>
            <width>160</width>
          </plugin>
        </visual>
        <velocity_decay>
          <linear>0</linear>
          <angular>0</angular>
        </velocity_decay>
        <self_collide>0</self_collide>
        <kinematic>0</kinematic>
        <gravity>1</gravity>
        <enable_wind>0</enable_wind>
      </link>
      <link name='lcd2'>
        <pose>0.4 0 1.0856 2.0071 -0 0</pose>
        <collision name='collision2'>
          <geometry>
            <box>
              <size>0.4758 0.35685 0.01</size>
            </box>
          </geometry>
          <max_contacts>10</max_contacts>
          <surface>
            <bounce/>
            <friction>
              <ode/>
              <torsional>
                <ode/>
              </torsional>
            </friction>
            <contact>
              <ode/>
            </contact>
          </surface>
        </collision>
        <visual name='visual2'>
          <geometry>
            <box>
              <size>0.4758 0.35685 0.01</size>
            </box>
          </geometry>
          <material>
            <ambient>0.69 0.69 0.69 1</ambient>
            <diffuse>0.69 0.69 0.69 1</diffuse>
            <specular>0.1 0.1 0.1 1</specular>
            <emissive>0 0 0 0</emissive>
          </material>
          <plugin name='display_video_controller2' filename='libgazebo_ros_video.so'>
            <robotNamespace>monitor2</robotNamespace>
            <topicName>image2</topicName>
            <height>120</height>
            <width>160</width>
          </plugin>
        </visual>
        <velocity_decay>
          <linear>0</linear>
          <angular>0</angular>
        </velocity_decay>
        <self_collide>0</self_collide>
        <kinematic>0</kinematic>
        <gravity>1</gravity>
        <enable_wind>0</enable_wind>
      </link>
    </model>
    <model name='Cattle_signal'>
      <link name='support_structure'>
        <pose>0 0 0 0 -0 0</pose>
        <visual name='base'>
          <geometry>
            <box>
              <size>0.305 0.2 0.05</size>
            </box>
          </geometry>
        </visual>
        <collision name='base'>
          <geometry>
            <box>
              <size>0.305 0.2 0.05</size>
            </box>
          </geometry>
          <max_contacts>10</max_contacts>
          <surface>
            <contact>
              <ode/>
            </contact>
            <bounce/>
            <friction>
              <torsional>
                <ode/>
              </torsional>
              <ode/>
            </friction>
          </surface>
        </collision>
        <visual name='vertical_post'>
          <pose>0 0 0.385 0 -0 0</pose>
          <geometry>
            <box>
              <size>0.0305 0.0305 0.82</size>
            </box>
          </geometry>
        </visual>
        <collision name='vertical_post'>
          <pose>0 0 0.385 0 -0 0</pose>
          <geometry>
            <box>
              <size>0.0305 0.0305 0.82</size>
            </box>
          </geometry>
          <max_contacts>10</max_contacts>
          <surface>
            <contact>
              <ode/>
            </contact>
            <bounce/>
            <friction>
              <torsional>
                <ode/>
              </torsional>
              <ode/>
            </friction>
          </surface>
        </collision>
        <self_collide>0</self_collide>
        <inertial>
          <pose>0 0 0 0 -0 0</pose>
          <inertia>
            <ixx>1</ixx>
            <ixy>0</ixy>
            <ixz>0</ixz>
            <iyy>1</iyy>
            <iyz>0</iyz>
            <izz>1</izz>
          </inertia>
          <mass>1</mass>
        </inertial>
        <enable_wind>0</enable_wind>
        <kinematic>0</kinematic>
      </link>
      <joint name='postAndPictogram' type='revolute'>
        <parent>support_structure</parent>
        <child>pictogram</child>
        <axis>
          <xyz expressed_in='__model__'>0 0 1</xyz>
          <limit>
            <upper>0</upper>
            <lower>0</lower>
          </limit>
          <dynamics>
            <spring_reference>0</spring_reference>
            <spring_stiffness>0</spring_stiffness>
          </dynamics>
        </axis>
      </joint>
      <link name='pictogram'>
        <pose>0 -0.0225 0.75 0 -0 0</pose>
        <visual name='pictogram'>
          <geometry>
            <mesh>
              <uri>model://CattleSignal/signal.dae</uri>
            </mesh>
          </geometry>
          <material>
            <script>
              <uri>model://CattleSignal/materials/scripts</uri>
              <uri>model://CattleSignal/materials/textures</uri>
              <name>Signal/Cattle</name>
            </script>
          </material>
        </visual>
        <self_collide>0</self_collide>
        <inertial>
          <pose>0 0 0 0 -0 0</pose>
          <inertia>
            <ixx>1</ixx>
            <ixy>0</ixy>
            <ixz>0</ixz>
            <iyy>1</iyy>
            <iyz>0</iyz>
            <izz>1</izz>
          </inertia>
          <mass>1</mass>
        </inertial>
        <enable_wind>0</enable_wind>
        <kinematic>0</kinematic>
      </link>
      <pose>3.12983 -2.57071 0 0 -0 0</pose>
    </model>
    <model name='Cattle_signal_0'>
      <link name='support_structure'>
        <pose>0 0 0 0 -0 0</pose>
        <visual name='base'>
          <geometry>
            <box>
              <size>0.305 0.2 0.05</size>
            </box>
          </geometry>
        </visual>
        <collision name='base'>
          <geometry>
            <box>
              <size>0.305 0.2 0.05</size>
            </box>
          </geometry>
          <max_contacts>10</max_contacts>
          <surface>
            <contact>
              <ode/>
            </contact>
            <bounce/>
            <friction>
              <torsional>
                <ode/>
              </torsional>
              <ode/>
            </friction>
          </surface>
        </collision>
        <visual name='vertical_post'>
          <pose>0 0 0.385 0 -0 0</pose>
          <geometry>
            <box>
              <size>0.0305 0.0305 0.82</size>
            </box>
          </geometry>
        </visual>
        <collision name='vertical_post'>
          <pose>0 0 0.385 0 -0 0</pose>
          <geometry>
            <box>
              <size>0.0305 0.0305 0.82</size>
            </box>
          </geometry>
          <max_contacts>10</max_contacts>
          <surface>
            <contact>
              <ode/>
            </contact>
            <bounce/>
            <friction>
              <torsional>
                <ode/>
              </torsional>
              <ode/>
            </friction>
          </surface>
        </collision>
        <self_collide>0</self_collide>
        <inertial>
          <pose>0 0 0 0 -0 0</pose>
          <inertia>
            <ixx>1</ixx>
            <ixy>0</ixy>
            <ixz>0</ixz>
            <iyy>1</iyy>
            <iyz>0</iyz>
            <izz>1</izz>
          </inertia>
          <mass>1</mass>
        </inertial>
        <enable_wind>0</enable_wind>
        <kinematic>0</kinematic>
      </link>
      <joint name='postAndPictogram' type='revolute'>
        <parent>support_structure</parent>
        <child>pictogram</child>
        <axis>
          <xyz expressed_in='__model__'>0 0 1</xyz>
          <limit>
            <upper>0</upper>
            <lower>0</lower>
          </limit>
          <dynamics>
            <spring_reference>0</spring_reference>
            <spring_stiffness>0</spring_stiffness>
          </dynamics>
        </axis>
      </joint>
      <link name='pictogram'>
        <pose>0 -0.0225 0.75 0 -0 0</pose>
        <visual name='pictogram'>
          <geometry>
            <mesh>
              <uri>model://CattleSignal/signal.dae</uri>
            </mesh>
          </geometry>
          <material>
            <script>
              <uri>model://CattleSignal/materials/scripts</uri>
              <uri>model://CattleSignal/materials/textures</uri>
              <name>Signal/Cattle</name>
            </script>
          </material>
        </visual>
        <self_collide>0</self_collide>
        <inertial>
          <pose>0 0 0 0 -0 0</pose>
          <inertia>
            <ixx>1</ixx>
            <ixy>0</ixy>
            <ixz>0</ixz>
            <iyy>1</iyy>
            <iyz>0</iyz>
            <izz>1</izz>
          </inertia>
          <mass>1</mass>
        </inertial>
        <enable_wind>0</enable_wind>
        <kinematic>0</kinematic>
      </link>
      <pose>2.48498 -2.56275 0 0 -0 0</pose>
    </model>
    <model name='Depression_signal'>
      <link name='support_structure'>
        <pose>0 0 0 0 -0 0</pose>
        <visual name='base'>
          <geometry>
            <box>
              <size>0.305 0.2 0.05</size>
            </box>
          </geometry>
        </visual>
        <collision name='base'>
          <geometry>
            <box>
              <size>0.305 0.2 0.05</size>
            </box>
          </geometry>
          <max_contacts>10</max_contacts>
          <surface>
            <contact>
              <ode/>
            </contact>
            <bounce/>
            <friction>
              <torsional>
                <ode/>
              </torsional>
              <ode/>
            </friction>
          </surface>
        </collision>
        <visual name='vertical_post'>
          <pose>0 0 0.385 0 -0 0</pose>
          <geometry>
            <box>
              <size>0.0305 0.0305 0.82</size>
            </box>
          </geometry>
        </visual>
        <collision name='vertical_post'>
          <pose>0 0 0.385 0 -0 0</pose>
          <geometry>
            <box>
              <size>0.0305 0.0305 0.82</size>
            </box>
          </geometry>
          <max_contacts>10</max_contacts>
          <surface>
            <contact>
              <ode/>
            </contact>
            <bounce/>
            <friction>
              <torsional>
                <ode/>
              </torsional>
              <ode/>
            </friction>
          </surface>
        </collision>
        <self_collide>0</self_collide>
        <inertial>
          <pose>0 0 0 0 -0 0</pose>
          <inertia>
            <ixx>1</ixx>
            <ixy>0</ixy>
            <ixz>0</ixz>
            <iyy>1</iyy>
            <iyz>0</iyz>
            <izz>1</izz>
          </inertia>
          <mass>1</mass>
        </inertial>
        <enable_wind>0</enable_wind>
        <kinematic>0</kinematic>
      </link>
      <joint name='postAndPictogram' type='revolute'>
        <parent>support_structure</parent>
        <child>pictogram</child>
        <axis>
          <xyz expressed_in='__model__'>0 0 1</xyz>
          <limit>
            <upper>0</upper>
            <lower>0</lower>
          </limit>
          <dynamics>
            <spring_reference>0</spring_reference>
            <spring_stiffness>0</spring_stiffness>
          </dynamics>
        </axis>
      </joint>
      <link name='pictogram'>
        <pose>0 -0.0225 0.75 0 -0 0</pose>
        <visual name='pictogram'>
          <geometry>
            <mesh>
              <uri>model://DepressionSignal/signal.dae</uri>
            </mesh>
          </geometry>
          <material>
            <script>
              <uri>model://DepressionSignal/materials/scripts</uri>
              <uri>model://DepressionSignal/materials/textures</uri>
              <name>Signal/Depression</name>
            </script>
          </material>
        </visual>
        <self_collide>0</self_collide>
        <inertial>
          <pose>0 0 0 0 -0 0</pose>
          <inertia>
            <ixx>1</ixx>
            <ixy>0</ixy>
            <ixz>0</ixz>
            <iyy>1</iyy>
            <iyz>0</iyz>
            <izz>1</izz>
          </inertia>
          <mass>1</mass>
        </inertial>
        <enable_wind>0</enable_wind>
        <kinematic>0</kinematic>
      </link>
      <pose>1.85708 -2.71735 0 0 -0 0</pose>
    </model>
    <model name='Depression_signal_0'>
      <link name='support_structure'>
        <pose>0 0 0 0 -0 0</pose>
        <visual name='base'>
          <geometry>
            <box>
              <size>0.305 0.2 0.05</size>
            </box>
          </geometry>
        </visual>
        <collision name='base'>
          <geometry>
            <box>
              <size>0.305 0.2 0.05</size>
            </box>
          </geometry>
          <max_contacts>10</max_contacts>
          <surface>
            <contact>
              <ode/>
            </contact>
            <bounce/>
            <friction>
              <torsional>
                <ode/>
              </torsional>
              <ode/>
            </friction>
          </surface>
        </collision>
        <visual name='vertical_post'>
          <pose>0 0 0.385 0 -0 0</pose>
          <geometry>
            <box>
              <size>0.0305 0.0305 0.82</size>
            </box>
          </geometry>
        </visual>
        <collision name='vertical_post'>
          <pose>0 0 0.385 0 -0 0</pose>
          <geometry>
            <box>
              <size>0.0305 0.0305 0.82</size>
            </box>
          </geometry>
          <max_contacts>10</max_contacts>
          <surface>
            <contact>
              <ode/>
            </contact>
            <bounce/>
            <friction>
              <torsional>
                <ode/>
              </torsional>
              <ode/>
            </friction>
          </surface>
        </collision>
        <self_collide>0</self_collide>
        <inertial>
          <pose>0 0 0 0 -0 0</pose>
          <inertia>
            <ixx>1</ixx>
            <ixy>0</ixy>
            <ixz>0</ixz>
            <iyy>1</iyy>
            <iyz>0</iyz>
            <izz>1</izz>
          </inertia>
          <mass>1</mass>
        </inertial>
        <enable_wind>0</enable_wind>
        <kinematic>0</kinematic>
      </link>
      <joint name='postAndPictogram' type='revolute'>
        <parent>support_structure</parent>
        <child>pictogram</child>
        <axis>
          <xyz expressed_in='__model__'>0 0 1</xyz>
          <limit>
            <upper>0</upper>
            <lower>0</lower>
          </limit>
          <dynamics>
            <spring_reference>0</spring_reference>
            <spring_stiffness>0</spring_stiffness>
          </dynamics>
        </axis>
      </joint>
      <link name='pictogram'>
        <pose>0 -0.0225 0.75 0 -0 0</pose>
        <visual name='pictogram'>
          <geometry>
            <mesh>
              <uri>model://DepressionSignal/signal.dae</uri>
            </mesh>
          </geometry>
          <material>
            <script>
              <uri>model://DepressionSignal/materials/scripts</uri>
              <uri>model://DepressionSignal/materials/textures</uri>
              <name>Signal/Depression</name>
            </script>
          </material>
        </visual>
        <self_collide>0</self_collide>
        <inertial>
          <pose>0 0 0 0 -0 0</pose>
          <inertia>
            <ixx>1</ixx>
            <ixy>0</ixy>
            <ixz>0</ixz>
            <iyy>1</iyy>
            <iyz>0</iyz>
            <izz>1</izz>
          </inertia>
          <mass>1</mass>
        </inertial>
        <enable_wind>0</enable_wind>
        <kinematic>0</kinematic>
      </link>
      <pose>1.32479 -2.81574 0 0 -0 0</pose>
    </model>
    <model name='Other_Dangers_signal'>
      <link name='support_structure'>
        <pose>0 0 0 0 -0 0</pose>
        <visual name='base'>
          <geometry>
            <box>
              <size>0.305 0.2 0.05</size>
            </box>
          </geometry>
        </visual>
        <collision name='base'>
          <geometry>
            <box>
              <size>0.305 0.2 0.05</size>
            </box>
          </geometry>
          <max_contacts>10</max_contacts>
          <surface>
            <contact>
              <ode/>
            </contact>
            <bounce/>
            <friction>
              <torsional>
                <ode/>
              </torsional>
              <ode/>
            </friction>
          </surface>
        </collision>
        <visual name='vertical_post'>
          <pose>0 0 0.385 0 -0 0</pose>
          <geometry>
            <box>
              <size>0.0305 0.0305 0.82</size>
            </box>
          </geometry>
        </visual>
        <collision name='vertical_post'>
          <pose>0 0 0.385 0 -0 0</pose>
          <geometry>
            <box>
              <size>0.0305 0.0305 0.82</size>
            </box>
          </geometry>
          <max_contacts>10</max_contacts>
          <surface>
            <contact>
              <ode/>
            </contact>
            <bounce/>
            <friction>
              <torsional>
                <ode/>
              </torsional>
              <ode/>
            </friction>
          </surface>
        </collision>
        <self_collide>0</self_collide>
        <inertial>
          <pose>0 0 0 0 -0 0</pose>
          <inertia>
            <ixx>1</ixx>
            <ixy>0</ixy>
            <ixz>0</ixz>
            <iyy>1</iyy>
            <iyz>0</iyz>
            <izz>1</izz>
          </inertia>
          <mass>1</mass>
        </inertial>
        <enable_wind>0</enable_wind>
        <kinematic>0</kinematic>
      </link>
      <joint name='postAndPictogram' type='revolute'>
        <parent>support_structure</parent>
        <child>pictogram</child>
        <axis>
          <xyz expressed_in='__model__'>0 0 1</xyz>
          <limit>
            <upper>0</upper>
            <lower>0</lower>
          </limit>
          <dynamics>
            <spring_reference>0</spring_reference>
            <spring_stiffness>0</spring_stiffness>
          </dynamics>
        </axis>
      </joint>
      <link name='pictogram'>
        <pose>0 -0.0225 0.75 0 -0 0</pose>
        <visual name='pictogram'>
          <geometry>
            <mesh>
              <uri>model://OtherDangersSignal/signal.dae</uri>
            </mesh>
          </geometry>
          <material>
            <script>
              <uri>model://OtherDangersSignal/materials/scripts</uri>
              <uri>model://OtherDangersSignal/materials/textures</uri>
              <name>Signal/OtherDangers</name>
            </script>
          </material>
        </visual>
        <self_collide>0</self_collide>
        <inertial>
          <pose>0 0 0 0 -0 0</pose>
          <inertia>
            <ixx>1</ixx>
            <ixy>0</ixy>
            <ixz>0</ixz>
            <iyy>1</iyy>
            <iyz>0</iyz>
            <izz>1</izz>
          </inertia>
          <mass>1</mass>
        </inertial>
        <enable_wind>0</enable_wind>
        <kinematic>0</kinematic>
      </link>
      <pose>0.847609 -2.8766 0 0 -0 0</pose>
    </model>
    <model name='Other_Dangers_signal_0'>
      <link name='support_structure'>
        <pose>0 0 0 0 -0 0</pose>
        <visual name='base'>
          <geometry>
            <box>
              <size>0.305 0.2 0.05</size>
            </box>
          </geometry>
        </visual>
        <collision name='base'>
          <geometry>
            <box>
              <size>0.305 0.2 0.05</size>
            </box>
          </geometry>
          <max_contacts>10</max_contacts>
          <surface>
            <contact>
              <ode/>
            </contact>
            <bounce/>
            <friction>
              <torsional>
                <ode/>
              </torsional>
              <ode/>
            </friction>
          </surface>
        </collision>
        <visual name='vertical_post'>
          <pose>0 0 0.385 0 -0 0</pose>
          <geometry>
            <box>
              <size>0.0305 0.0305 0.82</size>
            </box>
          </geometry>
        </visual>
        <collision name='vertical_post'>
          <pose>0 0 0.385 0 -0 0</pose>
          <geometry>
            <box>
              <size>0.0305 0.0305 0.82</size>
            </box>
          </geometry>
          <max_contacts>10</max_contacts>
          <surface>
            <contact>
              <ode/>
            </contact>
            <bounce/>
            <friction>
              <torsional>
                <ode/>
              </torsional>
              <ode/>
            </friction>
          </surface>
        </collision>
        <self_collide>0</self_collide>
        <inertial>
          <pose>0 0 0 0 -0 0</pose>
          <inertia>
            <ixx>1</ixx>
            <ixy>0</ixy>
            <ixz>0</ixz>
            <iyy>1</iyy>
            <iyz>0</iyz>
            <izz>1</izz>
          </inertia>
          <mass>1</mass>
        </inertial>
        <enable_wind>0</enable_wind>
        <kinematic>0</kinematic>
      </link>
      <joint name='postAndPictogram' type='revolute'>
        <parent>support_structure</parent>
        <child>pictogram</child>
        <axis>
          <xyz expressed_in='__model__'>0 0 1</xyz>
          <limit>
            <upper>0</upper>
            <lower>0</lower>
          </limit>
          <dynamics>
            <spring_reference>0</spring_reference>
            <spring_stiffness>0</spring_stiffness>
          </dynamics>
        </axis>
      </joint>
      <link name='pictogram'>
        <pose>0 -0.0225 0.75 0 -0 0</pose>
        <visual name='pictogram'>
          <geometry>
            <mesh>
              <uri>model://OtherDangersSignal/signal.dae</uri>
            </mesh>
          </geometry>
          <material>
            <script>
              <uri>model://OtherDangersSignal/materials/scripts</uri>
              <uri>model://OtherDangersSignal/materials/textures</uri>
              <name>Signal/OtherDangers</name>
            </script>
          </material>
        </visual>
        <self_collide>0</self_collide>
        <inertial>
          <pose>0 0 0 0 -0 0</pose>
          <inertia>
            <ixx>1</ixx>
            <ixy>0</ixy>
            <ixz>0</ixz>
            <iyy>1</iyy>
            <iyz>0</iyz>
            <izz>1</izz>
          </inertia>
          <mass>1</mass>
        </inertial>
        <enable_wind>0</enable_wind>
        <kinematic>0</kinematic>
      </link>
      <pose>0.465416 -2.92072 0 0 -0 0</pose>
    </model>
    <model name='Road_Narrow_signal'>
      <link name='support_structure'>
        <pose>0 0 0 0 -0 0</pose>
        <visual name='base'>
          <geometry>
            <box>
              <size>0.305 0.2 0.05</size>
            </box>
          </geometry>
        </visual>
        <collision name='base'>
          <geometry>
            <box>
              <size>0.305 0.2 0.05</size>
            </box>
          </geometry>
          <max_contacts>10</max_contacts>
          <surface>
            <contact>
              <ode/>
            </contact>
            <bounce/>
            <friction>
              <torsional>
                <ode/>
              </torsional>
              <ode/>
            </friction>
          </surface>
        </collision>
        <visual name='vertical_post'>
          <pose>0 0 0.385 0 -0 0</pose>
          <geometry>
            <box>
              <size>0.0305 0.0305 0.82</size>
            </box>
          </geometry>
        </visual>
        <collision name='vertical_post'>
          <pose>0 0 0.385 0 -0 0</pose>
          <geometry>
            <box>
              <size>0.0305 0.0305 0.82</size>
            </box>
          </geometry>
          <max_contacts>10</max_contacts>
          <surface>
            <contact>
              <ode/>
            </contact>
            <bounce/>
            <friction>
              <torsional>
                <ode/>
              </torsional>
              <ode/>
            </friction>
          </surface>
        </collision>
        <self_collide>0</self_collide>
        <inertial>
          <pose>0 0 0 0 -0 0</pose>
          <inertia>
            <ixx>1</ixx>
            <ixy>0</ixy>
            <ixz>0</ixz>
            <iyy>1</iyy>
            <iyz>0</iyz>
            <izz>1</izz>
          </inertia>
          <mass>1</mass>
        </inertial>
        <enable_wind>0</enable_wind>
        <kinematic>0</kinematic>
      </link>
      <joint name='postAndPictogram' type='revolute'>
        <parent>support_structure</parent>
        <child>pictogram</child>
        <axis>
          <xyz expressed_in='__model__'>0 0 1</xyz>
          <limit>
            <upper>0</upper>
            <lower>0</lower>
          </limit>
          <dynamics>
            <spring_reference>0</spring_reference>
            <spring_stiffness>0</spring_stiffness>
          </dynamics>
        </axis>
      </joint>
      <link name='pictogram'>
        <pose>0 -0.0225 0.75 0 -0 0</pose>
        <visual name='pictogram'>
          <geometry>
            <mesh>
              <uri>model://RoadNarrowSignal/signal.dae</uri>
            </mesh>
          </geometry>
          <material>
            <script>
              <uri>model://RoadNarrowSignal/materials/scripts</uri>
              <uri>model://RoadNarrowSignal/materials/textures</uri>
              <name>Signal/RoadNarrow</name>
            </script>
          </material>
        </visual>
        <self_collide>0</self_collide>
        <inertial>
          <pose>0 0 0 0 -0 0</pose>
          <inertia>
            <ixx>1</ixx>
            <ixy>0</ixy>
            <ixz>0</ixz>
            <iyy>1</iyy>
            <iyz>0</iyz>
            <izz>1</izz>
          </inertia>
          <mass>1</mass>
        </inertial>
        <enable_wind>0</enable_wind>
        <kinematic>0</kinematic>
      </link>
      <pose>0.042232 -2.8478 0 0 -0 0</pose>
    </model>
    <model name='Road_Narrow_signal_0'>
      <link name='support_structure'>
        <pose>0 0 0 0 -0 0</pose>
        <visual name='base'>
          <geometry>
            <box>
              <size>0.305 0.2 0.05</size>
            </box>
          </geometry>
        </visual>
        <collision name='base'>
          <geometry>
            <box>
              <size>0.305 0.2 0.05</size>
            </box>
          </geometry>
          <max_contacts>10</max_contacts>
          <surface>
            <contact>
              <ode/>
            </contact>
            <bounce/>
            <friction>
              <torsional>
                <ode/>
              </torsional>
              <ode/>
            </friction>
          </surface>
        </collision>
        <visual name='vertical_post'>
          <pose>0 0 0.385 0 -0 0</pose>
          <geometry>
            <box>
              <size>0.0305 0.0305 0.82</size>
            </box>
          </geometry>
        </visual>
        <collision name='vertical_post'>
          <pose>0 0 0.385 0 -0 0</pose>
          <geometry>
            <box>
              <size>0.0305 0.0305 0.82</size>
            </box>
          </geometry>
          <max_contacts>10</max_contacts>
          <surface>
            <contact>
              <ode/>
            </contact>
            <bounce/>
            <friction>
              <torsional>
                <ode/>
              </torsional>
              <ode/>
            </friction>
          </surface>
        </collision>
        <self_collide>0</self_collide>
        <inertial>
          <pose>0 0 0 0 -0 0</pose>
          <inertia>
            <ixx>1</ixx>
            <ixy>0</ixy>
            <ixz>0</ixz>
            <iyy>1</iyy>
            <iyz>0</iyz>
            <izz>1</izz>
          </inertia>
          <mass>1</mass>
        </inertial>
        <enable_wind>0</enable_wind>
        <kinematic>0</kinematic>
      </link>
      <joint name='postAndPictogram' type='revolute'>
        <parent>support_structure</parent>
        <child>pictogram</child>
        <axis>
          <xyz expressed_in='__model__'>0 0 1</xyz>
          <limit>
            <upper>0</upper>
            <lower>0</lower>
          </limit>
          <dynamics>
            <spring_reference>0</spring_reference>
            <spring_stiffness>0</spring_stiffness>
          </dynamics>
        </axis>
      </joint>
      <link name='pictogram'>
        <pose>0 -0.0225 0.75 0 -0 0</pose>
        <visual name='pictogram'>
          <geometry>
            <mesh>
              <uri>model://RoadNarrowSignal/signal.dae</uri>
            </mesh>
          </geometry>
          <material>
            <script>
              <uri>model://RoadNarrowSignal/materials/scripts</uri>
              <uri>model://RoadNarrowSignal/materials/textures</uri>
              <name>Signal/RoadNarrow</name>
            </script>
          </material>
        </visual>
        <self_collide>0</self_collide>
        <inertial>
          <pose>0 0 0 0 -0 0</pose>
          <inertia>
            <ixx>1</ixx>
            <ixy>0</ixy>
            <ixz>0</ixz>
            <iyy>1</iyy>
            <iyz>0</iyz>
            <izz>1</izz>
          </inertia>
          <mass>1</mass>
        </inertial>
        <enable_wind>0</enable_wind>
        <kinematic>0</kinematic>
      </link>
      <pose>-0.376908 -2.76438 0 0 -0 0</pose>
    </model>
    <model name='Crosswalk_signal'>
      <link name='support_structure'>
        <pose>0 0 0 0 -0 0</pose>
        <visual name='base'>
          <geometry>
            <box>
              <size>0.305 0.2 0.05</size>
            </box>
          </geometry>
        </visual>
        <collision name='base'>
          <geometry>
            <box>
              <size>0.305 0.2 0.05</size>
            </box>
          </geometry>
          <max_contacts>10</max_contacts>
          <surface>
            <contact>
              <ode/>
            </contact>
            <bounce/>
            <friction>
              <torsional>
                <ode/>
              </torsional>
              <ode/>
            </friction>
          </surface>
        </collision>
        <visual name='vertical_post'>
          <pose>0 0 0.385 0 -0 0</pose>
          <geometry>
            <box>
              <size>0.0305 0.0305 0.82</size>
            </box>
          </geometry>
        </visual>
        <collision name='vertical_post'>
          <pose>0 0 0.385 0 -0 0</pose>
          <geometry>
            <box>
              <size>0.0305 0.0305 0.82</size>
            </box>
          </geometry>
          <max_contacts>10</max_contacts>
          <surface>
            <contact>
              <ode/>
            </contact>
            <bounce/>
            <friction>
              <torsional>
                <ode/>
              </torsional>
              <ode/>
            </friction>
          </surface>
        </collision>
        <self_collide>0</self_collide>
        <inertial>
          <pose>0 0 0 0 -0 0</pose>
          <inertia>
            <ixx>1</ixx>
            <ixy>0</ixy>
            <ixz>0</ixz>
            <iyy>1</iyy>
            <iyz>0</iyz>
            <izz>1</izz>
          </inertia>
          <mass>1</mass>
        </inertial>
        <enable_wind>0</enable_wind>
        <kinematic>0</kinematic>
      </link>
      <joint name='postAndPictogram' type='revolute'>
        <parent>support_structure</parent>
        <child>pictogram</child>
        <axis>
          <xyz expressed_in='__model__'>0 0 1</xyz>
          <limit>
            <upper>0</upper>
            <lower>0</lower>
          </limit>
          <dynamics>
            <spring_reference>0</spring_reference>
            <spring_stiffness>0</spring_stiffness>
          </dynamics>
        </axis>
      </joint>
      <link name='pictogram'>
        <pose>0 -0.0225 0.75 0 -0 0</pose>
        <visual name='pictogram'>
          <geometry>
            <mesh>
              <uri>model://CrosswalkSignal/signal.dae</uri>
            </mesh>
          </geometry>
          <material>
            <script>
              <uri>model://CrosswalkSignal/materials/scripts</uri>
              <uri>model://CrosswalkSignal/materials/textures</uri>
              <name>Signal/Crosswalk</name>
            </script>
          </material>
        </visual>
        <self_collide>0</self_collide>
        <inertial>
          <pose>0 0 0 0 -0 0</pose>
          <inertia>
            <ixx>1</ixx>
            <ixy>0</ixy>
            <ixz>0</ixz>
            <iyy>1</iyy>
            <iyz>0</iyz>
            <izz>1</izz>
          </inertia>
          <mass>1</mass>
        </inertial>
        <enable_wind>0</enable_wind>
        <kinematic>0</kinematic>
      </link>
      <pose>3.03872 -3.70085 0 0 -0 0</pose>
    </model>
    <model name='Crosswalk_signal_0'>
      <link name='support_structure'>
        <pose>0 0 0 0 -0 0</pose>
        <visual name='base'>
          <geometry>
            <box>
              <size>0.305 0.2 0.05</size>
            </box>
          </geometry>
        </visual>
        <collision name='base'>
          <geometry>
            <box>
              <size>0.305 0.2 0.05</size>
            </box>
          </geometry>
          <max_contacts>10</max_contacts>
          <surface>
            <contact>
              <ode/>
            </contact>
            <bounce/>
            <friction>
              <torsional>
                <ode/>
              </torsional>
              <ode/>
            </friction>
          </surface>
        </collision>
        <visual name='vertical_post'>
          <pose>0 0 0.385 0 -0 0</pose>
          <geometry>
            <box>
              <size>0.0305 0.0305 0.82</size>
            </box>
          </geometry>
        </visual>
        <collision name='vertical_post'>
          <pose>0 0 0.385 0 -0 0</pose>
          <geometry>
            <box>
              <size>0.0305 0.0305 0.82</size>
            </box>
          </geometry>
          <max_contacts>10</max_contacts>
          <surface>
            <contact>
              <ode/>
            </contact>
            <bounce/>
            <friction>
              <torsional>
                <ode/>
              </torsional>
              <ode/>
            </friction>
          </surface>
        </collision>
        <self_collide>0</self_collide>
        <inertial>
          <pose>0 0 0 0 -0 0</pose>
          <inertia>
            <ixx>1</ixx>
            <ixy>0</ixy>
            <ixz>0</ixz>
            <iyy>1</iyy>
            <iyz>0</iyz>
            <izz>1</izz>
          </inertia>
          <mass>1</mass>
        </inertial>
        <enable_wind>0</enable_wind>
        <kinematic>0</kinematic>
      </link>
      <joint name='postAndPictogram' type='revolute'>
        <parent>support_structure</parent>
        <child>pictogram</child>
        <axis>
          <xyz expressed_in='__model__'>0 0 1</xyz>
          <limit>
            <upper>0</upper>
            <lower>0</lower>
          </limit>
          <dynamics>
            <spring_reference>0</spring_reference>
            <spring_stiffness>0</spring_stiffness>
          </dynamics>
        </axis>
      </joint>
      <link name='pictogram'>
        <pose>0 -0.0225 0.75 0 -0 0</pose>
        <visual name='pictogram'>
          <geometry>
            <mesh>
              <uri>model://CrosswalkSignal/signal.dae</uri>
            </mesh>
          </geometry>
          <material>
            <script>
              <uri>model://CrosswalkSignal/materials/scripts</uri>
              <uri>model://CrosswalkSignal/materials/textures</uri>
              <name>Signal/Crosswalk</name>
            </script>
          </material>
        </visual>
        <self_collide>0</self_collide>
        <inertial>
          <pose>0 0 0 0 -0 0</pose>
          <inertia>
            <ixx>1</ixx>
            <ixy>0</ixy>
            <ixz>0</ixz>
            <iyy>1</iyy>
            <iyz>0</iyz>
            <izz>1</izz>
          </inertia>
          <mass>1</mass>
        </inertial>
        <enable_wind>0</enable_wind>
        <kinematic>0</kinematic>
      </link>
      <pose>2.46652 -3.68993 0 0 -0 0</pose>
    </model>
    <model name='Hospital_signal'>
      <link name='support_structure'>
        <pose>0 0 0 0 -0 0</pose>
        <visual name='base'>
          <geometry>
            <box>
              <size>0.305 0.2 0.05</size>
            </box>
          </geometry>
        </visual>
        <collision name='base'>
          <geometry>
            <box>
              <size>0.305 0.2 0.05</size>
            </box>
          </geometry>
          <max_contacts>10</max_contacts>
          <surface>
            <contact>
              <ode/>
            </contact>
            <bounce/>
            <friction>
              <torsional>
                <ode/>
              </torsional>
              <ode/>
            </friction>
          </surface>
        </collision>
        <visual name='vertical_post'>
          <pose>0 0 0.385 0 -0 0</pose>
          <geometry>
            <box>
              <size>0.0305 0.0305 0.82</size>
            </box>
          </geometry>
        </visual>
        <collision name='vertical_post'>
          <pose>0 0 0.385 0 -0 0</pose>
          <geometry>
            <box>
              <size>0.0305 0.0305 0.82</size>
            </box>
          </geometry>
          <max_contacts>10</max_contacts>
          <surface>
            <contact>
              <ode/>
            </contact>
            <bounce/>
            <friction>
              <torsional>
                <ode/>
              </torsional>
              <ode/>
            </friction>
          </surface>
        </collision>
        <self_collide>0</self_collide>
        <inertial>
          <pose>0 0 0 0 -0 0</pose>
          <inertia>
            <ixx>1</ixx>
            <ixy>0</ixy>
            <ixz>0</ixz>
            <iyy>1</iyy>
            <iyz>0</iyz>
            <izz>1</izz>
          </inertia>
          <mass>1</mass>
        </inertial>
        <enable_wind>0</enable_wind>
        <kinematic>0</kinematic>
      </link>
      <joint name='postAndPictogram' type='revolute'>
        <parent>support_structure</parent>
        <child>pictogram</child>
        <axis>
          <xyz expressed_in='__model__'>0 0 1</xyz>
          <limit>
            <upper>0</upper>
            <lower>0</lower>
          </limit>
          <dynamics>
            <spring_reference>0</spring_reference>
            <spring_stiffness>0</spring_stiffness>
          </dynamics>
        </axis>
      </joint>
      <link name='pictogram'>
        <pose>0 -0.0225 0.75 0 -0 0</pose>
        <visual name='pictogram'>
          <geometry>
            <mesh>
              <uri>model://HospitalSignal/signal.dae</uri>
            </mesh>
          </geometry>
          <material>
            <script>
              <uri>model://HospitalSignal/materials/scripts</uri>
              <uri>model://HospitalSignal/materials/textures</uri>
              <name>Signal/Hospital</name>
            </script>
          </material>
        </visual>
        <self_collide>0</self_collide>
        <inertial>
          <pose>0 0 0 0 -0 0</pose>
          <inertia>
            <ixx>1</ixx>
            <ixy>0</ixy>
            <ixz>0</ixz>
            <iyy>1</iyy>
            <iyz>0</iyz>
            <izz>1</izz>
          </inertia>
          <mass>1</mass>
        </inertial>
        <enable_wind>0</enable_wind>
        <kinematic>0</kinematic>
      </link>
      <pose>1.84299 -3.67268 0 0 -0 0</pose>
    </model>
    <model name='Hospital_signal_0'>
      <link name='support_structure'>
        <pose>0 0 0 0 -0 0</pose>
        <visual name='base'>
          <geometry>
            <box>
              <size>0.305 0.2 0.05</size>
            </box>
          </geometry>
        </visual>
        <collision name='base'>
          <geometry>
            <box>
              <size>0.305 0.2 0.05</size>
            </box>
          </geometry>
          <max_contacts>10</max_contacts>
          <surface>
            <contact>
              <ode/>
            </contact>
            <bounce/>
            <friction>
              <torsional>
                <ode/>
              </torsional>
              <ode/>
            </friction>
          </surface>
        </collision>
        <visual name='vertical_post'>
          <pose>0 0 0.385 0 -0 0</pose>
          <geometry>
            <box>
              <size>0.0305 0.0305 0.82</size>
            </box>
          </geometry>
        </visual>
        <collision name='vertical_post'>
          <pose>0 0 0.385 0 -0 0</pose>
          <geometry>
            <box>
              <size>0.0305 0.0305 0.82</size>
            </box>
          </geometry>
          <max_contacts>10</max_contacts>
          <surface>
            <contact>
              <ode/>
            </contact>
            <bounce/>
            <friction>
              <torsional>
                <ode/>
              </torsional>
              <ode/>
            </friction>
          </surface>
        </collision>
        <self_collide>0</self_collide>
        <inertial>
          <pose>0 0 0 0 -0 0</pose>
          <inertia>
            <ixx>1</ixx>
            <ixy>0</ixy>
            <ixz>0</ixz>
            <iyy>1</iyy>
            <iyz>0</iyz>
            <izz>1</izz>
          </inertia>
          <mass>1</mass>
        </inertial>
        <enable_wind>0</enable_wind>
        <kinematic>0</kinematic>
      </link>
      <joint name='postAndPictogram' type='revolute'>
        <parent>support_structure</parent>
        <child>pictogram</child>
        <axis>
          <xyz expressed_in='__model__'>0 0 1</xyz>
          <limit>
            <upper>0</upper>
            <lower>0</lower>
          </limit>
          <dynamics>
            <spring_reference>0</spring_reference>
            <spring_stiffness>0</spring_stiffness>
          </dynamics>
        </axis>
      </joint>
      <link name='pictogram'>
        <pose>0 -0.0225 0.75 0 -0 0</pose>
        <visual name='pictogram'>
          <geometry>
            <mesh>
              <uri>model://HospitalSignal/signal.dae</uri>
            </mesh>
          </geometry>
          <material>
            <script>
              <uri>model://HospitalSignal/materials/scripts</uri>
              <uri>model://HospitalSignal/materials/textures</uri>
              <name>Signal/Hospital</name>
            </script>
          </material>
        </visual>
        <self_collide>0</self_collide>
        <inertial>
          <pose>0 0 0 0 -0 0</pose>
          <inertia>
            <ixx>1</ixx>
            <ixy>0</ixy>
            <ixz>0</ixz>
            <iyy>1</iyy>
            <iyz>0</iyz>
            <izz>1</izz>
          </inertia>
          <mass>1</mass>
        </inertial>
        <enable_wind>0</enable_wind>
        <kinematic>0</kinematic>
      </link>
      <pose>1.32997 -3.63315 0 0 -0 0</pose>
    </model>
    <model name='Park_signal'>
      <link name='support_structure'>
        <pose>0 0 0 0 -0 0</pose>
        <visual name='base'>
          <geometry>
            <box>
              <size>0.305 0.2 0.05</size>
            </box>
          </geometry>
        </visual>
        <collision name='base'>
          <geometry>
            <box>
              <size>0.305 0.2 0.05</size>
            </box>
          </geometry>
          <max_contacts>10</max_contacts>
          <surface>
            <contact>
              <ode/>
            </contact>
            <bounce/>
            <friction>
              <torsional>
                <ode/>
              </torsional>
              <ode/>
            </friction>
          </surface>
        </collision>
        <visual name='vertical_post'>
          <pose>0 0 0.385 0 -0 0</pose>
          <geometry>
            <box>
              <size>0.0305 0.0305 0.82</size>
            </box>
          </geometry>
        </visual>
        <collision name='vertical_post'>
          <pose>0 0 0.385 0 -0 0</pose>
          <geometry>
            <box>
              <size>0.0305 0.0305 0.82</size>
            </box>
          </geometry>
          <max_contacts>10</max_contacts>
          <surface>
            <contact>
              <ode/>
            </contact>
            <bounce/>
            <friction>
              <torsional>
                <ode/>
              </torsional>
              <ode/>
            </friction>
          </surface>
        </collision>
        <self_collide>0</self_collide>
        <inertial>
          <pose>0 0 0 0 -0 0</pose>
          <inertia>
            <ixx>1</ixx>
            <ixy>0</ixy>
            <ixz>0</ixz>
            <iyy>1</iyy>
            <iyz>0</iyz>
            <izz>1</izz>
          </inertia>
          <mass>1</mass>
        </inertial>
        <enable_wind>0</enable_wind>
        <kinematic>0</kinematic>
      </link>
      <joint name='postAndPictogram' type='revolute'>
        <parent>support_structure</parent>
        <child>pictogram</child>
        <axis>
          <xyz expressed_in='__model__'>0 0 1</xyz>
          <limit>
            <upper>0</upper>
            <lower>0</lower>
          </limit>
          <dynamics>
            <spring_reference>0</spring_reference>
            <spring_stiffness>0</spring_stiffness>
          </dynamics>
        </axis>
      </joint>
      <link name='pictogram'>
        <pose>0 -0.0225 0.75 0 -0 0</pose>
        <visual name='pictogram'>
          <geometry>
            <mesh>
              <uri>model://ParkSignal/signal.dae</uri>
            </mesh>
          </geometry>
          <material>
            <script>
              <uri>model://ParkSignal/materials/scripts</uri>
              <uri>model://ParkSignal/materials/textures</uri>
              <name>Signal/Park</name>
            </script>
          </material>
        </visual>
        <self_collide>0</self_collide>
        <inertial>
          <pose>0 0 0 0 -0 0</pose>
          <inertia>
            <ixx>1</ixx>
            <ixy>0</ixy>
            <ixz>0</ixz>
            <iyy>1</iyy>
            <iyz>0</iyz>
            <izz>1</izz>
          </inertia>
          <mass>1</mass>
        </inertial>
        <enable_wind>0</enable_wind>
        <kinematic>0</kinematic>
      </link>
      <pose>0.862907 -3.6666 0 0 -0 0</pose>
    </model>
    <model name='Park_signal_0'>
      <link name='support_structure'>
        <pose>0 0 0 0 -0 0</pose>
        <visual name='base'>
          <geometry>
            <box>
              <size>0.305 0.2 0.05</size>
            </box>
          </geometry>
        </visual>
        <collision name='base'>
          <geometry>
            <box>
              <size>0.305 0.2 0.05</size>
            </box>
          </geometry>
          <max_contacts>10</max_contacts>
          <surface>
            <contact>
              <ode/>
            </contact>
            <bounce/>
            <friction>
              <torsional>
                <ode/>
              </torsional>
              <ode/>
            </friction>
          </surface>
        </collision>
        <visual name='vertical_post'>
          <pose>0 0 0.385 0 -0 0</pose>
          <geometry>
            <box>
              <size>0.0305 0.0305 0.82</size>
            </box>
          </geometry>
        </visual>
        <collision name='vertical_post'>
          <pose>0 0 0.385 0 -0 0</pose>
          <geometry>
            <box>
              <size>0.0305 0.0305 0.82</size>
            </box>
          </geometry>
          <max_contacts>10</max_contacts>
          <surface>
            <contact>
              <ode/>
            </contact>
            <bounce/>
            <friction>
              <torsional>
                <ode/>
              </torsional>
              <ode/>
            </friction>
          </surface>
        </collision>
        <self_collide>0</self_collide>
        <inertial>
          <pose>0 0 0 0 -0 0</pose>
          <inertia>
            <ixx>1</ixx>
            <ixy>0</ixy>
            <ixz>0</ixz>
            <iyy>1</iyy>
            <iyz>0</iyz>
            <izz>1</izz>
          </inertia>
          <mass>1</mass>
        </inertial>
        <enable_wind>0</enable_wind>
        <kinematic>0</kinematic>
      </link>
      <joint name='postAndPictogram' type='revolute'>
        <parent>support_structure</parent>
        <child>pictogram</child>
        <axis>
          <xyz expressed_in='__model__'>0 0 1</xyz>
          <limit>
            <upper>0</upper>
            <lower>0</lower>
          </limit>
          <dynamics>
            <spring_reference>0</spring_reference>
            <spring_stiffness>0</spring_stiffness>
          </dynamics>
        </axis>
      </joint>
      <link name='pictogram'>
        <pose>0 -0.0225 0.75 0 -0 0</pose>
        <visual name='pictogram'>
          <geometry>
            <mesh>
              <uri>model://ParkSignal/signal.dae</uri>
            </mesh>
          </geometry>
          <material>
            <script>
              <uri>model://ParkSignal/materials/scripts</uri>
              <uri>model://ParkSignal/materials/textures</uri>
              <name>Signal/Park</name>
            </script>
          </material>
        </visual>
        <self_collide>0</self_collide>
        <inertial>
          <pose>0 0 0 0 -0 0</pose>
          <inertia>
            <ixx>1</ixx>
            <ixy>0</ixy>
            <ixz>0</ixz>
            <iyy>1</iyy>
            <iyz>0</iyz>
            <izz>1</izz>
          </inertia>
          <mass>1</mass>
        </inertial>
        <enable_wind>0</enable_wind>
        <kinematic>0</kinematic>
      </link>
      <pose>0.501237 -3.54172 0 0 -0 0</pose>
    </model>
    <model name='RMV_Signal'>
      <link name='support_structure'>
        <pose>0 0 0 0 -0 0</pose>
        <visual name='base'>
          <geometry>
            <box>
              <size>0.305 0.2 0.05</size>
            </box>
          </geometry>
        </visual>
        <collision name='base'>
          <geometry>
            <box>
              <size>0.305 0.2 0.05</size>
            </box>
          </geometry>
          <max_contacts>10</max_contacts>
          <surface>
            <contact>
              <ode/>
            </contact>
            <bounce/>
            <friction>
              <torsional>
                <ode/>
              </torsional>
              <ode/>
            </friction>
          </surface>
        </collision>
        <visual name='vertical_post'>
          <pose>0 0 0.385 0 -0 0</pose>
          <geometry>
            <box>
              <size>0.0305 0.0305 0.82</size>
            </box>
          </geometry>
        </visual>
        <collision name='vertical_post'>
          <pose>0 0 0.385 0 -0 0</pose>
          <geometry>
            <box>
              <size>0.0305 0.0305 0.82</size>
            </box>
          </geometry>
          <max_contacts>10</max_contacts>
          <surface>
            <contact>
              <ode/>
            </contact>
            <bounce/>
            <friction>
              <torsional>
                <ode/>
              </torsional>
              <ode/>
            </friction>
          </surface>
        </collision>
        <self_collide>0</self_collide>
        <inertial>
          <pose>0 0 0 0 -0 0</pose>
          <inertia>
            <ixx>1</ixx>
            <ixy>0</ixy>
            <ixz>0</ixz>
            <iyy>1</iyy>
            <iyz>0</iyz>
            <izz>1</izz>
          </inertia>
          <mass>1</mass>
        </inertial>
        <enable_wind>0</enable_wind>
        <kinematic>0</kinematic>
      </link>
      <joint name='postAndPictogram' type='revolute'>
        <parent>support_structure</parent>
        <child>pictogram</child>
        <axis>
          <xyz expressed_in='__model__'>0 0 1</xyz>
          <limit>
            <upper>0</upper>
            <lower>0</lower>
          </limit>
          <dynamics>
            <spring_reference>0</spring_reference>
            <spring_stiffness>0</spring_stiffness>
          </dynamics>
        </axis>
      </joint>
      <link name='pictogram'>
        <pose>0 -0.0225 0.75 0 -0 0</pose>
        <visual name='pictogram'>
          <geometry>
            <mesh>
              <uri>model://RMVSignal/signal.dae</uri>
            </mesh>
          </geometry>
          <material>
            <script>
              <uri>model://RMVSignal/materials/scripts</uri>
              <uri>model://RMVSignal/materials/textures</uri>
              <name>Signal/RMV</name>
            </script>
          </material>
        </visual>
        <self_collide>0</self_collide>
        <inertial>
          <pose>0 0 0 0 -0 0</pose>
          <inertia>
            <ixx>1</ixx>
            <ixy>0</ixy>
            <ixz>0</ixz>
            <iyy>1</iyy>
            <iyz>0</iyz>
            <izz>1</izz>
          </inertia>
          <mass>1</mass>
        </inertial>
        <enable_wind>0</enable_wind>
        <kinematic>0</kinematic>
      </link>
      <pose>0.045439 -3.49118 0 0 -0 0</pose>
    </model>
    <model name='RMV_Signal_0'>
      <link name='support_structure'>
        <pose>0 0 0 0 -0 0</pose>
        <visual name='base'>
          <geometry>
            <box>
              <size>0.305 0.2 0.05</size>
            </box>
          </geometry>
        </visual>
        <collision name='base'>
          <geometry>
            <box>
              <size>0.305 0.2 0.05</size>
            </box>
          </geometry>
          <max_contacts>10</max_contacts>
          <surface>
            <contact>
              <ode/>
            </contact>
            <bounce/>
            <friction>
              <torsional>
                <ode/>
              </torsional>
              <ode/>
            </friction>
          </surface>
        </collision>
        <visual name='vertical_post'>
          <pose>0 0 0.385 0 -0 0</pose>
          <geometry>
            <box>
              <size>0.0305 0.0305 0.82</size>
            </box>
          </geometry>
        </visual>
        <collision name='vertical_post'>
          <pose>0 0 0.385 0 -0 0</pose>
          <geometry>
            <box>
              <size>0.0305 0.0305 0.82</size>
            </box>
          </geometry>
          <max_contacts>10</max_contacts>
          <surface>
            <contact>
              <ode/>
            </contact>
            <bounce/>
            <friction>
              <torsional>
                <ode/>
              </torsional>
              <ode/>
            </friction>
          </surface>
        </collision>
        <self_collide>0</self_collide>
        <inertial>
          <pose>0 0 0 0 -0 0</pose>
          <inertia>
            <ixx>1</ixx>
            <ixy>0</ixy>
            <ixz>0</ixz>
            <iyy>1</iyy>
            <iyz>0</iyz>
            <izz>1</izz>
          </inertia>
          <mass>1</mass>
        </inertial>
        <enable_wind>0</enable_wind>
        <kinematic>0</kinematic>
      </link>
      <joint name='postAndPictogram' type='revolute'>
        <parent>support_structure</parent>
        <child>pictogram</child>
        <axis>
          <xyz expressed_in='__model__'>0 0 1</xyz>
          <limit>
            <upper>0</upper>
            <lower>0</lower>
          </limit>
          <dynamics>
            <spring_reference>0</spring_reference>
            <spring_stiffness>0</spring_stiffness>
          </dynamics>
        </axis>
      </joint>
      <link name='pictogram'>
        <pose>0 -0.0225 0.75 0 -0 0</pose>
        <visual name='pictogram'>
          <geometry>
            <mesh>
              <uri>model://RMVSignal/signal.dae</uri>
            </mesh>
          </geometry>
          <material>
            <script>
              <uri>model://RMVSignal/materials/scripts</uri>
              <uri>model://RMVSignal/materials/textures</uri>
              <name>Signal/RMV</name>
            </script>
          </material>
        </visual>
        <self_collide>0</self_collide>
        <inertial>
          <pose>0 0 0 0 -0 0</pose>
          <inertia>
            <ixx>1</ixx>
            <ixy>0</ixy>
            <ixz>0</ixz>
            <iyy>1</iyy>
            <iyz>0</iyz>
            <izz>1</izz>
          </inertia>
          <mass>1</mass>
        </inertial>
        <enable_wind>0</enable_wind>
        <kinematic>0</kinematic>
      </link>
      <pose>-0.42666 -3.37031 0 0 -0 0</pose>
    </model>
    <model name='Lights_signal'>
      <link name='support_structure'>
        <pose>0 0 0 0 -0 0</pose>
        <visual name='base'>
          <geometry>
            <box>
              <size>0.305 0.2 0.05</size>
            </box>
          </geometry>
        </visual>
        <collision name='base'>
          <geometry>
            <box>
              <size>0.305 0.2 0.05</size>
            </box>
          </geometry>
          <max_contacts>10</max_contacts>
          <surface>
            <contact>
              <ode/>
            </contact>
            <bounce/>
            <friction>
              <torsional>
                <ode/>
              </torsional>
              <ode/>
            </friction>
          </surface>
        </collision>
        <visual name='vertical_post'>
          <pose>0 0 0.385 0 -0 0</pose>
          <geometry>
            <box>
              <size>0.0305 0.0305 0.82</size>
            </box>
          </geometry>
        </visual>
        <collision name='vertical_post'>
          <pose>0 0 0.385 0 -0 0</pose>
          <geometry>
            <box>
              <size>0.0305 0.0305 0.82</size>
            </box>
          </geometry>
          <max_contacts>10</max_contacts>
          <surface>
            <contact>
              <ode/>
            </contact>
            <bounce/>
            <friction>
              <torsional>
                <ode/>
              </torsional>
              <ode/>
            </friction>
          </surface>
        </collision>
        <self_collide>0</self_collide>
        <inertial>
          <pose>0 0 0 0 -0 0</pose>
          <inertia>
            <ixx>1</ixx>
            <ixy>0</ixy>
            <ixz>0</ixz>
            <iyy>1</iyy>
            <iyz>0</iyz>
            <izz>1</izz>
          </inertia>
          <mass>1</mass>
        </inertial>
        <enable_wind>0</enable_wind>
        <kinematic>0</kinematic>
      </link>
      <joint name='postAndPictogram' type='revolute'>
        <parent>support_structure</parent>
        <child>pictogram</child>
        <axis>
          <xyz expressed_in='__model__'>0 0 1</xyz>
          <limit>
            <upper>0</upper>
            <lower>0</lower>
          </limit>
          <dynamics>
            <spring_reference>0</spring_reference>
            <spring_stiffness>0</spring_stiffness>
          </dynamics>
        </axis>
      </joint>
      <link name='pictogram'>
        <pose>0 -0.0225 0.75 0 -0 0</pose>
        <visual name='pictogram'>
          <geometry>
            <mesh>
              <uri>model://LightsSignal/signal.dae</uri>
            </mesh>
          </geometry>
          <material>
            <script>
              <uri>model://LightsSignal/materials/scripts</uri>
              <uri>model://LightsSignal/materials/textures</uri>
              <name>Signal/Lights</name>
            </script>
          </material>
        </visual>
        <self_collide>0</self_collide>
        <inertial>
          <pose>0 0 0 0 -0 0</pose>
          <inertia>
            <ixx>1</ixx>
            <ixy>0</ixy>
            <ixz>0</ixz>
            <iyy>1</iyy>
            <iyz>0</iyz>
            <izz>1</izz>
          </inertia>
          <mass>1</mass>
        </inertial>
        <enable_wind>0</enable_wind>
        <kinematic>0</kinematic>
      </link>
      <pose>2.97813 -4.37486 0 0 -0 0</pose>
    </model>
    <model name='Lights_signal_0'>
      <link name='support_structure'>
        <pose>0 0 0 0 -0 0</pose>
        <visual name='base'>
          <geometry>
            <box>
              <size>0.305 0.2 0.05</size>
            </box>
          </geometry>
        </visual>
        <collision name='base'>
          <geometry>
            <box>
              <size>0.305 0.2 0.05</size>
            </box>
          </geometry>
          <max_contacts>10</max_contacts>
          <surface>
            <contact>
              <ode/>
            </contact>
            <bounce/>
            <friction>
              <torsional>
                <ode/>
              </torsional>
              <ode/>
            </friction>
          </surface>
        </collision>
        <visual name='vertical_post'>
          <pose>0 0 0.385 0 -0 0</pose>
          <geometry>
            <box>
              <size>0.0305 0.0305 0.82</size>
            </box>
          </geometry>
        </visual>
        <collision name='vertical_post'>
          <pose>0 0 0.385 0 -0 0</pose>
          <geometry>
            <box>
              <size>0.0305 0.0305 0.82</size>
            </box>
          </geometry>
          <max_contacts>10</max_contacts>
          <surface>
            <contact>
              <ode/>
            </contact>
            <bounce/>
            <friction>
              <torsional>
                <ode/>
              </torsional>
              <ode/>
            </friction>
          </surface>
        </collision>
        <self_collide>0</self_collide>
        <inertial>
          <pose>0 0 0 0 -0 0</pose>
          <inertia>
            <ixx>1</ixx>
            <ixy>0</ixy>
            <ixz>0</ixz>
            <iyy>1</iyy>
            <iyz>0</iyz>
            <izz>1</izz>
          </inertia>
          <mass>1</mass>
        </inertial>
        <enable_wind>0</enable_wind>
        <kinematic>0</kinematic>
      </link>
      <joint name='postAndPictogram' type='revolute'>
        <parent>support_structure</parent>
        <child>pictogram</child>
        <axis>
          <xyz expressed_in='__model__'>0 0 1</xyz>
          <limit>
            <upper>0</upper>
            <lower>0</lower>
          </limit>
          <dynamics>
            <spring_reference>0</spring_reference>
            <spring_stiffness>0</spring_stiffness>
          </dynamics>
        </axis>
      </joint>
      <link name='pictogram'>
        <pose>0 -0.0225 0.75 0 -0 0</pose>
        <visual name='pictogram'>
          <geometry>
            <mesh>
              <uri>model://LightsSignal/signal.dae</uri>
            </mesh>
          </geometry>
          <material>
            <script>
              <uri>model://LightsSignal/materials/scripts</uri>
              <uri>model://LightsSignal/materials/textures</uri>
              <name>Signal/Lights</name>
            </script>
          </material>
        </visual>
        <self_collide>0</self_collide>
        <inertial>
          <pose>0 0 0 0 -0 0</pose>
          <inertia>
            <ixx>1</ixx>
            <ixy>0</ixy>
            <ixz>0</ixz>
            <iyy>1</iyy>
            <iyz>0</iyz>
            <izz>1</izz>
          </inertia>
          <mass>1</mass>
        </inertial>
        <enable_wind>0</enable_wind>
        <kinematic>0</kinematic>
      </link>
      <pose>2.46512 -4.28646 0 0 -0 0</pose>
    </model>
    <model name='Round_About_signal'>
      <link name='support_structure'>
        <pose>0 0 0 0 -0 0</pose>
        <visual name='base'>
          <geometry>
            <box>
              <size>0.305 0.2 0.05</size>
            </box>
          </geometry>
        </visual>
        <collision name='base'>
          <geometry>
            <box>
              <size>0.305 0.2 0.05</size>
            </box>
          </geometry>
          <max_contacts>10</max_contacts>
          <surface>
            <contact>
              <ode/>
            </contact>
            <bounce/>
            <friction>
              <torsional>
                <ode/>
              </torsional>
              <ode/>
            </friction>
          </surface>
        </collision>
        <visual name='vertical_post'>
          <pose>0 0 0.385 0 -0 0</pose>
          <geometry>
            <box>
              <size>0.0305 0.0305 0.82</size>
            </box>
          </geometry>
        </visual>
        <collision name='vertical_post'>
          <pose>0 0 0.385 0 -0 0</pose>
          <geometry>
            <box>
              <size>0.0305 0.0305 0.82</size>
            </box>
          </geometry>
          <max_contacts>10</max_contacts>
          <surface>
            <contact>
              <ode/>
            </contact>
            <bounce/>
            <friction>
              <torsional>
                <ode/>
              </torsional>
              <ode/>
            </friction>
          </surface>
        </collision>
        <self_collide>0</self_collide>
        <inertial>
          <pose>0 0 0 0 -0 0</pose>
          <inertia>
            <ixx>1</ixx>
            <ixy>0</ixy>
            <ixz>0</ixz>
            <iyy>1</iyy>
            <iyz>0</iyz>
            <izz>1</izz>
          </inertia>
          <mass>1</mass>
        </inertial>
        <enable_wind>0</enable_wind>
        <kinematic>0</kinematic>
      </link>
      <joint name='postAndPictogram' type='revolute'>
        <parent>support_structure</parent>
        <child>pictogram</child>
        <axis>
          <xyz expressed_in='__model__'>0 0 1</xyz>
          <limit>
            <upper>0</upper>
            <lower>0</lower>
          </limit>
          <dynamics>
            <spring_reference>0</spring_reference>
            <spring_stiffness>0</spring_stiffness>
          </dynamics>
        </axis>
      </joint>
      <link name='pictogram'>
        <pose>0 -0.0225 0.75 0 -0 0</pose>
        <visual name='pictogram'>
          <geometry>
            <mesh>
              <uri>model://RoundAboutSignal/signal.dae</uri>
            </mesh>
          </geometry>
          <material>
            <script>
              <uri>model://RoundAboutSignal/materials/scripts</uri>
              <uri>model://RoundAboutSignal/materials/textures</uri>
              <name>Signal/RoundAbout</name>
            </script>
          </material>
        </visual>
        <self_collide>0</self_collide>
        <inertial>
          <pose>0 0 0 0 -0 0</pose>
          <inertia>
            <ixx>1</ixx>
            <ixy>0</ixy>
            <ixz>0</ixz>
            <iyy>1</iyy>
            <iyz>0</iyz>
            <izz>1</izz>
          </inertia>
          <mass>1</mass>
        </inertial>
        <enable_wind>0</enable_wind>
        <kinematic>0</kinematic>
      </link>
      <pose>1.8182 -4.16666 0 0 -0 0</pose>
    </model>
    <model name='Round_About_signal_0'>
      <link name='support_structure'>
        <pose>0 0 0 0 -0 0</pose>
        <visual name='base'>
          <geometry>
            <box>
              <size>0.305 0.2 0.05</size>
            </box>
          </geometry>
        </visual>
        <collision name='base'>
          <geometry>
            <box>
              <size>0.305 0.2 0.05</size>
            </box>
          </geometry>
          <max_contacts>10</max_contacts>
          <surface>
            <contact>
              <ode/>
            </contact>
            <bounce/>
            <friction>
              <torsional>
                <ode/>
              </torsional>
              <ode/>
            </friction>
          </surface>
        </collision>
        <visual name='vertical_post'>
          <pose>0 0 0.385 0 -0 0</pose>
          <geometry>
            <box>
              <size>0.0305 0.0305 0.82</size>
            </box>
          </geometry>
        </visual>
        <collision name='vertical_post'>
          <pose>0 0 0.385 0 -0 0</pose>
          <geometry>
            <box>
              <size>0.0305 0.0305 0.82</size>
            </box>
          </geometry>
          <max_contacts>10</max_contacts>
          <surface>
            <contact>
              <ode/>
            </contact>
            <bounce/>
            <friction>
              <torsional>
                <ode/>
              </torsional>
              <ode/>
            </friction>
          </surface>
        </collision>
        <self_collide>0</self_collide>
        <inertial>
          <pose>0 0 0 0 -0 0</pose>
          <inertia>
            <ixx>1</ixx>
            <ixy>0</ixy>
            <ixz>0</ixz>
            <iyy>1</iyy>
            <iyz>0</iyz>
            <izz>1</izz>
          </inertia>
          <mass>1</mass>
        </inertial>
        <enable_wind>0</enable_wind>
        <kinematic>0</kinematic>
      </link>
      <joint name='postAndPictogram' type='revolute'>
        <parent>support_structure</parent>
        <child>pictogram</child>
        <axis>
          <xyz expressed_in='__model__'>0 0 1</xyz>
          <limit>
            <upper>0</upper>
            <lower>0</lower>
          </limit>
          <dynamics>
            <spring_reference>0</spring_reference>
            <spring_stiffness>0</spring_stiffness>
          </dynamics>
        </axis>
      </joint>
      <link name='pictogram'>
        <pose>0 -0.0225 0.75 0 -0 0</pose>
        <visual name='pictogram'>
          <geometry>
            <mesh>
              <uri>model://RoundAboutSignal/signal.dae</uri>
            </mesh>
          </geometry>
          <material>
            <script>
              <uri>model://RoundAboutSignal/materials/scripts</uri>
              <uri>model://RoundAboutSignal/materials/textures</uri>
              <name>Signal/RoundAbout</name>
            </script>
          </material>
        </visual>
        <self_collide>0</self_collide>
        <inertial>
          <pose>0 0 0 0 -0 0</pose>
          <inertia>
            <ixx>1</ixx>
            <ixy>0</ixy>
            <ixz>0</ixz>
            <iyy>1</iyy>
            <iyz>0</iyz>
            <izz>1</izz>
          </inertia>
          <mass>1</mass>
        </inertial>
        <enable_wind>0</enable_wind>
        <kinematic>0</kinematic>
      </link>
      <pose>1.33034 -4.27131 0 0 -0 0</pose>
    </model>
    <model name='Turn_Left_signal'>
      <link name='support_structure'>
        <pose>0 0 0 0 -0 0</pose>
        <visual name='base'>
          <geometry>
            <box>
              <size>0.305 0.2 0.05</size>
            </box>
          </geometry>
        </visual>
        <collision name='base'>
          <geometry>
            <box>
              <size>0.305 0.2 0.05</size>
            </box>
          </geometry>
          <max_contacts>10</max_contacts>
          <surface>
            <contact>
              <ode/>
            </contact>
            <bounce/>
            <friction>
              <torsional>
                <ode/>
              </torsional>
              <ode/>
            </friction>
          </surface>
        </collision>
        <visual name='vertical_post'>
          <pose>0 0 0.385 0 -0 0</pose>
          <geometry>
            <box>
              <size>0.0305 0.0305 0.82</size>
            </box>
          </geometry>
        </visual>
        <collision name='vertical_post'>
          <pose>0 0 0.385 0 -0 0</pose>
          <geometry>
            <box>
              <size>0.0305 0.0305 0.82</size>
            </box>
          </geometry>
          <max_contacts>10</max_contacts>
          <surface>
            <contact>
              <ode/>
            </contact>
            <bounce/>
            <friction>
              <torsional>
                <ode/>
              </torsional>
              <ode/>
            </friction>
          </surface>
        </collision>
        <self_collide>0</self_collide>
        <inertial>
          <pose>0 0 0 0 -0 0</pose>
          <inertia>
            <ixx>1</ixx>
            <ixy>0</ixy>
            <ixz>0</ixz>
            <iyy>1</iyy>
            <iyz>0</iyz>
            <izz>1</izz>
          </inertia>
          <mass>1</mass>
        </inertial>
        <enable_wind>0</enable_wind>
        <kinematic>0</kinematic>
      </link>
      <joint name='postAndPictogram' type='revolute'>
        <parent>support_structure</parent>
        <child>pictogram</child>
        <axis>
          <xyz expressed_in='__model__'>0 0 1</xyz>
          <limit>
            <upper>0</upper>
            <lower>0</lower>
          </limit>
          <dynamics>
            <spring_reference>0</spring_reference>
            <spring_stiffness>0</spring_stiffness>
          </dynamics>
        </axis>
      </joint>
      <link name='pictogram'>
        <pose>0 -0.0225 0.75 0 -0 0</pose>
        <visual name='pictogram'>
          <geometry>
            <mesh>
              <uri>model://TurnLeftSignal/signal.dae</uri>
            </mesh>
          </geometry>
          <material>
            <script>
              <uri>model://TurnLeftSignal/materials/scripts</uri>
              <uri>model://TurnLeftSignal/materials/textures</uri>
              <name>Signal/TurnLeft</name>
            </script>
          </material>
        </visual>
        <self_collide>0</self_collide>
        <inertial>
          <pose>0 0 0 0 -0 0</pose>
          <inertia>
            <ixx>1</ixx>
            <ixy>0</ixy>
            <ixz>0</ixz>
            <iyy>1</iyy>
            <iyz>0</iyz>
            <izz>1</izz>
          </inertia>
          <mass>1</mass>
        </inertial>
        <enable_wind>0</enable_wind>
        <kinematic>0</kinematic>
      </link>
      <pose>0.847167 -4.23374 0 0 -0 0</pose>
    </model>
    <model name='Turn_Left_signal_0'>
      <link name='support_structure'>
        <pose>0 0 0 0 -0 0</pose>
        <visual name='base'>
          <geometry>
            <box>
              <size>0.305 0.2 0.05</size>
            </box>
          </geometry>
        </visual>
        <collision name='base'>
          <geometry>
            <box>
              <size>0.305 0.2 0.05</size>
            </box>
          </geometry>
          <max_contacts>10</max_contacts>
          <surface>
            <contact>
              <ode/>
            </contact>
            <bounce/>
            <friction>
              <torsional>
                <ode/>
              </torsional>
              <ode/>
            </friction>
          </surface>
        </collision>
        <visual name='vertical_post'>
          <pose>0 0 0.385 0 -0 0</pose>
          <geometry>
            <box>
              <size>0.0305 0.0305 0.82</size>
            </box>
          </geometry>
        </visual>
        <collision name='vertical_post'>
          <pose>0 0 0.385 0 -0 0</pose>
          <geometry>
            <box>
              <size>0.0305 0.0305 0.82</size>
            </box>
          </geometry>
          <max_contacts>10</max_contacts>
          <surface>
            <contact>
              <ode/>
            </contact>
            <bounce/>
            <friction>
              <torsional>
                <ode/>
              </torsional>
              <ode/>
            </friction>
          </surface>
        </collision>
        <self_collide>0</self_collide>
        <inertial>
          <pose>0 0 0 0 -0 0</pose>
          <inertia>
            <ixx>1</ixx>
            <ixy>0</ixy>
            <ixz>0</ixz>
            <iyy>1</iyy>
            <iyz>0</iyz>
            <izz>1</izz>
          </inertia>
          <mass>1</mass>
        </inertial>
        <enable_wind>0</enable_wind>
        <kinematic>0</kinematic>
      </link>
      <joint name='postAndPictogram' type='revolute'>
        <parent>support_structure</parent>
        <child>pictogram</child>
        <axis>
          <xyz expressed_in='__model__'>0 0 1</xyz>
          <limit>
            <upper>0</upper>
            <lower>0</lower>
          </limit>
          <dynamics>
            <spring_reference>0</spring_reference>
            <spring_stiffness>0</spring_stiffness>
          </dynamics>
        </axis>
      </joint>
      <link name='pictogram'>
        <pose>0 -0.0225 0.75 0 -0 0</pose>
        <visual name='pictogram'>
          <geometry>
            <mesh>
              <uri>model://TurnLeftSignal/signal.dae</uri>
            </mesh>
          </geometry>
          <material>
            <script>
              <uri>model://TurnLeftSignal/materials/scripts</uri>
              <uri>model://TurnLeftSignal/materials/textures</uri>
              <name>Signal/TurnLeft</name>
            </script>
          </material>
        </visual>
        <self_collide>0</self_collide>
        <inertial>
          <pose>0 0 0 0 -0 0</pose>
          <inertia>
            <ixx>1</ixx>
            <ixy>0</ixy>
            <ixz>0</ixz>
            <iyy>1</iyy>
            <iyz>0</iyz>
            <izz>1</izz>
          </inertia>
          <mass>1</mass>
        </inertial>
        <enable_wind>0</enable_wind>
        <kinematic>0</kinematic>
      </link>
      <pose>0.420707 -4.06023 0 0 -0 0</pose>
    </model>
    <model name='Bus_signal'>
      <link name='support_structure'>
        <pose>0 0 0 0 -0 0</pose>
        <visual name='base'>
          <geometry>
            <box>
              <size>0.305 0.2 0.05</size>
            </box>
          </geometry>
        </visual>
        <collision name='base'>
          <geometry>
            <box>
              <size>0.305 0.2 0.05</size>
            </box>
          </geometry>
          <max_contacts>10</max_contacts>
          <surface>
            <contact>
              <ode/>
            </contact>
            <bounce/>
            <friction>
              <torsional>
                <ode/>
              </torsional>
              <ode/>
            </friction>
          </surface>
        </collision>
        <visual name='vertical_post'>
          <pose>0 0 0.385 0 -0 0</pose>
          <geometry>
            <box>
              <size>0.0305 0.0305 0.82</size>
            </box>
          </geometry>
        </visual>
        <collision name='vertical_post'>
          <pose>0 0 0.385 0 -0 0</pose>
          <geometry>
            <box>
              <size>0.0305 0.0305 0.82</size>
            </box>
          </geometry>
          <max_contacts>10</max_contacts>
          <surface>
            <contact>
              <ode/>
            </contact>
            <bounce/>
            <friction>
              <torsional>
                <ode/>
              </torsional>
              <ode/>
            </friction>
          </surface>
        </collision>
        <self_collide>0</self_collide>
        <inertial>
          <pose>0 0 0 0 -0 0</pose>
          <inertia>
            <ixx>1</ixx>
            <ixy>0</ixy>
            <ixz>0</ixz>
            <iyy>1</iyy>
            <iyz>0</iyz>
            <izz>1</izz>
          </inertia>
          <mass>1</mass>
        </inertial>
        <enable_wind>0</enable_wind>
        <kinematic>0</kinematic>
      </link>
      <joint name='postAndPictogram' type='revolute'>
        <parent>support_structure</parent>
        <child>pictogram</child>
        <axis>
          <xyz expressed_in='__model__'>0 0 1</xyz>
          <limit>
            <upper>0</upper>
            <lower>0</lower>
          </limit>
          <dynamics>
            <spring_reference>0</spring_reference>
            <spring_stiffness>0</spring_stiffness>
          </dynamics>
        </axis>
      </joint>
      <link name='pictogram'>
        <pose>0 -0.0225 0.75 0 -0 0</pose>
        <visual name='pictogram'>
          <geometry>
            <mesh>
              <uri>model://BusSignal/signal.dae</uri>
            </mesh>
          </geometry>
          <material>
            <script>
              <uri>model://BusSignal/materials/scripts</uri>
              <uri>model://BusSignal/materials/textures</uri>
              <name>Signal/Bus</name>
            </script>
          </material>
        </visual>
        <self_collide>0</self_collide>
        <inertial>
          <pose>0 0 0 0 -0 0</pose>
          <inertia>
            <ixx>1</ixx>
            <ixy>0</ixy>
            <ixz>0</ixz>
            <iyy>1</iyy>
            <iyz>0</iyz>
            <izz>1</izz>
          </inertia>
          <mass>1</mass>
        </inertial>
        <enable_wind>0</enable_wind>
        <kinematic>0</kinematic>
      </link>
      <pose>-0.059626 -3.94339 0 0 -0 0</pose>
    </model>
    <model name='Bus_signal_0'>
      <link name='support_structure'>
        <pose>0 0 0 0 -0 0</pose>
        <visual name='base'>
          <geometry>
            <box>
              <size>0.305 0.2 0.05</size>
            </box>
          </geometry>
        </visual>
        <collision name='base'>
          <geometry>
            <box>
              <size>0.305 0.2 0.05</size>
            </box>
          </geometry>
          <max_contacts>10</max_contacts>
          <surface>
            <contact>
              <ode/>
            </contact>
            <bounce/>
            <friction>
              <torsional>
                <ode/>
              </torsional>
              <ode/>
            </friction>
          </surface>
        </collision>
        <visual name='vertical_post'>
          <pose>0 0 0.385 0 -0 0</pose>
          <geometry>
            <box>
              <size>0.0305 0.0305 0.82</size>
            </box>
          </geometry>
        </visual>
        <collision name='vertical_post'>
          <pose>0 0 0.385 0 -0 0</pose>
          <geometry>
            <box>
              <size>0.0305 0.0305 0.82</size>
            </box>
          </geometry>
          <max_contacts>10</max_contacts>
          <surface>
            <contact>
              <ode/>
            </contact>
            <bounce/>
            <friction>
              <torsional>
                <ode/>
              </torsional>
              <ode/>
            </friction>
          </surface>
        </collision>
        <self_collide>0</self_collide>
        <inertial>
          <pose>0 0 0 0 -0 0</pose>
          <inertia>
            <ixx>1</ixx>
            <ixy>0</ixy>
            <ixz>0</ixz>
            <iyy>1</iyy>
            <iyz>0</iyz>
            <izz>1</izz>
          </inertia>
          <mass>1</mass>
        </inertial>
        <enable_wind>0</enable_wind>
        <kinematic>0</kinematic>
      </link>
      <joint name='postAndPictogram' type='revolute'>
        <parent>support_structure</parent>
        <child>pictogram</child>
        <axis>
          <xyz expressed_in='__model__'>0 0 1</xyz>
          <limit>
            <upper>0</upper>
            <lower>0</lower>
          </limit>
          <dynamics>
            <spring_reference>0</spring_reference>
            <spring_stiffness>0</spring_stiffness>
          </dynamics>
        </axis>
      </joint>
      <link name='pictogram'>
        <pose>0 -0.0225 0.75 0 -0 0</pose>
        <visual name='pictogram'>
          <geometry>
            <mesh>
              <uri>model://BusSignal/signal.dae</uri>
            </mesh>
          </geometry>
          <material>
            <script>
              <uri>model://BusSignal/materials/scripts</uri>
              <uri>model://BusSignal/materials/textures</uri>
              <name>Signal/Bus</name>
            </script>
          </material>
        </visual>
        <self_collide>0</self_collide>
        <inertial>
          <pose>0 0 0 0 -0 0</pose>
          <inertia>
            <ixx>1</ixx>
            <ixy>0</ixy>
            <ixz>0</ixz>
            <iyy>1</iyy>
            <iyz>0</iyz>
            <izz>1</izz>
          </inertia>
          <mass>1</mass>
        </inertial>
        <enable_wind>0</enable_wind>
        <kinematic>0</kinematic>
      </link>
      <pose>-0.516483 -3.69718 0 0 -0 0</pose>
    </model>
    <model name='prometheus'>
      <link name='base_footprint'>
        <inertial>
          <pose>0 0 0 0 -0 0</pose>
          <mass>2</mass>
          <inertia>
            <ixx>1</ixx>
            <ixy>0</ixy>
            <ixz>0</ixz>
            <iyy>1</iyy>
            <iyz>0</iyz>
            <izz>1</izz>
          </inertia>
        </inertial>
        <collision name='base_footprint_collision'>
          <pose>0 0 0 0 -0 0</pose>
          <geometry>
            <sphere>
              <radius>1e-08</radius>
            </sphere>
          </geometry>
          <surface>
            <contact>
              <ode/>
            </contact>
            <friction>
              <ode/>
              <torsional>
                <ode/>
              </torsional>
            </friction>
            <bounce/>
          </surface>
          <max_contacts>10</max_contacts>
        </collision>
        <collision name='base_footprint_fixed_joint_lump__base_link_collision_1'>
          <pose>0 0 0.19 0 -0 0</pose>
          <geometry>
            <box>
              <size>0.6 0.35 0.25</size>
            </box>
          </geometry>
          <max_contacts>10</max_contacts>
          <surface>
            <contact>
              <ode/>
            </contact>
            <bounce/>
            <friction>
              <torsional>
                <ode/>
              </torsional>
              <ode/>
            </friction>
          </surface>
        </collision>
        <collision name='base_footprint_fixed_joint_lump__bottom_front_camera_link_collision_2'>
          <pose>0.25 0 0.115 3.14151 -0 0</pose>
          <geometry>
            <box>
              <size>0.06 0.3 0.07</size>
            </box>
          </geometry>
          <max_contacts>10</max_contacts>
          <surface>
            <contact>
              <ode/>
            </contact>
            <bounce/>
            <friction>
              <torsional>
                <ode/>
              </torsional>
              <ode/>
            </friction>
          </surface>
        </collision>
        <collision name='base_footprint_fixed_joint_lump__top_front_camera_link_collision_3'>
          <pose>-0.22 0 0.6 0 0.4 0</pose>
          <geometry>
            <box>
              <size>0.06 0.3 0.07</size>
            </box>
          </geometry>
          <max_contacts>10</max_contacts>
          <surface>
            <contact>
              <ode/>
            </contact>
            <bounce/>
            <friction>
              <torsional>
                <ode/>
              </torsional>
              <ode/>
            </friction>
          </surface>
        </collision>
        <collision name='base_footprint_fixed_joint_lump__top_left_camera_link_collision_4'>
          <pose>-0.28 0.025 0.7 0 -0.3 0</pose>
          <geometry>
            <box>
              <size>0.015 0.03 0.027</size>
            </box>
          </geometry>
          <max_contacts>10</max_contacts>
          <surface>
            <contact>
              <ode/>
            </contact>
            <bounce/>
            <friction>
              <torsional>
                <ode/>
              </torsional>
              <ode/>
            </friction>
          </surface>
        </collision>
        <collision name='base_footprint_fixed_joint_lump__top_right_camera_link_collision_5'>
          <pose>-0.28 -0.025 0.7 0 -0.3 -0.7854</pose>
          <geometry>
            <box>
              <size>0.015 0.03 0.027</size>
            </box>
          </geometry>
          <max_contacts>10</max_contacts>
          <surface>
            <contact>
              <ode/>
            </contact>
            <bounce/>
            <friction>
              <torsional>
                <ode/>
              </torsional>
              <ode/>
            </friction>
          </surface>
        </collision>
        <visual name='base_footprint_fixed_joint_lump__base_link_visual'>
          <pose>0.3 -0.175 0.15 1.5708 -0 3.14159</pose>
          <geometry>
            <mesh>
              <scale>1 1 1</scale>
              <uri>file:////home/nel/catkin_ws/src/AutoMec-AD/prometheus_description/meshes/chassis.dae</uri>
            </mesh>
          </geometry>
        </visual>
        <visual name='base_footprint_fixed_joint_lump__bottom_front_camera_link_visual_1'>
          <pose>0.25 0 0.115 -3.14159 -8.4e-05 -1.5708</pose>
          <geometry>
            <mesh>
              <scale>1 1 1</scale>
              <uri>/home/nel/catkin_ws/src/AutoMec-AD/prometheus_description/meshes/kinect.dae</uri>
            </mesh>
          </geometry>
        </visual>
        <visual name='base_footprint_fixed_joint_lump__top_front_camera_link_visual_2'>
          <pose>-0.22 0 0.6 0.4 -1e-06 1.5708</pose>
          <geometry>
            <mesh>
              <scale>1 1 1</scale>
              <uri>/home/nel/catkin_ws/src/AutoMec-AD/prometheus_description/meshes/kinect.dae</uri>
            </mesh>
          </geometry>
        </visual>
        <visual name='base_footprint_fixed_joint_lump__top_left_camera_link_visual_3'>
          <pose>-0.28 0.025 0.7 0 -0.3 0</pose>
          <geometry>
            <box>
              <size>0.015 0.03 0.027</size>
            </box>
          </geometry>
        </visual>
        <visual name='base_footprint_fixed_joint_lump__top_right_camera_link_visual_4'>
          <pose>-0.28 -0.025 0.7 0 -0.3 -0.7854</pose>
          <geometry>
            <box>
              <size>0.015 0.03 0.027</size>
            </box>
          </geometry>
        </visual>
        <sensor name='kinect' type='depth'>
          <camera>
            <horizontal_fov>0.748397</horizontal_fov>
            <image>
              <width>1280</width>
              <height>1024</height>
              <format>R8G8B8</format>
            </image>
            <clip>
              <near>0.1</near>
              <far>10</far>
            </clip>
            <noise>
              <type>gaussian</type>
              <mean>0.5</mean>
              <stddev>1</stddev>
            </noise>
          </camera>
          <plugin name='kinect_plugin' filename='libgazebo_ros_openni_kinect.so'>
            <baseline>0.1</baseline>
            <alwaysOn>1</alwaysOn>
            <updateRate>0.0</updateRate>
            <cameraName>bottom_front_camera</cameraName>
            <imageTopicName>/bottom_front_camera/rgb/image_color</imageTopicName>
            <cameraInfoTopicName>/bottom_front_camera/rgb/camera_info</cameraInfoTopicName>
            <depthImageTopicName>/bottom_front_camera/depth_registered/image</depthImageTopicName>
            <depthImageInfoTopicName>/bottom_front_camera/depth_registered/camera_info</depthImageInfoTopicName>
            <pointCloudTopicName>/bottom_front_camera/depth_registered/points</pointCloudTopicName>
            <frameName>bottom_front_camera_optical_frame</frameName>
            <pointCloudCutoff>0.5</pointCloudCutoff>
            <pointCloudCutoffMax>2.0</pointCloudCutoffMax>
            <robotNamespace>/</robotNamespace>
          </plugin>
          <always_on>1</always_on>
          <update_rate>30</update_rate>
          <pose>0.25 0 0.115 3.14151 -0 0</pose>
        </sensor>
        <sensor name='kinect' type='depth'>
          <camera>
            <horizontal_fov>0.748397</horizontal_fov>
            <image>
              <width>1280</width>
              <height>1024</height>
              <format>R8G8B8</format>
            </image>
            <clip>
              <near>0.1</near>
              <far>10</far>
            </clip>
            <noise>
              <type>gaussian</type>
              <mean>0.5</mean>
              <stddev>1</stddev>
            </noise>
          </camera>
          <plugin name='kinect_plugin' filename='libgazebo_ros_openni_kinect.so'>
            <baseline>0.1</baseline>
            <alwaysOn>1</alwaysOn>
            <updateRate>0.0</updateRate>
            <cameraName>top_front_camera</cameraName>
            <imageTopicName>/top_front_camera/rgb/image_raw</imageTopicName>
            <cameraInfoTopicName>/top_front_camera/rgb/camera_info</cameraInfoTopicName>
            <depthImageTopicName>/top_front_camera/depth_registered/image</depthImageTopicName>
            <depthImageInfoTopicName>/top_front_camera/depth_registered/camera_info</depthImageInfoTopicName>
            <pointCloudTopicName>/top_front_camera/depth_registered/points</pointCloudTopicName>
            <frameName>top_front_camera_optical_frame</frameName>
            <pointCloudCutoff>0.5</pointCloudCutoff>
            <pointCloudCutoffMax>2.0</pointCloudCutoffMax>
            <robotNamespace>/</robotNamespace>
          </plugin>
          <always_on>1</always_on>
          <update_rate>30</update_rate>
          <pose>-0.22 0 0.6 0 0.4 0</pose>
        </sensor>
        <sensor name='Usb Camera' type='camera'>
          <always_on>1</always_on>
          <visualize>0</visualize>
          <camera>
            <horizontal_fov>1.0856</horizontal_fov>
            <image>
              <width>640</width>
              <height>480</height>
              <format>R8G8B8</format>
            </image>
            <clip>
              <near>0.03</near>
              <far>100</far>
            </clip>
          </camera>
          <plugin name='camera_controller' filename='libgazebo_ros_camera.so'>
            <alwaysOn>1</alwaysOn>
            <updateRate>30.0</updateRate>
            <cameraName>top_left_camera</cameraName>
            <frameName>top_left_camera_rgb_optical_frame</frameName>
            <imageTopicName>image_raw</imageTopicName>
            <cameraInfoTopicName>camera_info</cameraInfoTopicName>
            <hackBaseline>0.07</hackBaseline>
            <distortionK1>0.0</distortionK1>
            <distortionK2>0.0</distortionK2>
            <distortionK3>0.0</distortionK3>
            <distortionT1>0.0</distortionT1>
            <distortionT2>0.0</distortionT2>
            <robotNamespace>/</robotNamespace>
          </plugin>
          <pose>-0.28 0.025 0.7 0 -0.3 0</pose>
        </sensor>
        <sensor name='Usb Camera' type='camera'>
          <always_on>1</always_on>
          <visualize>0</visualize>
          <camera>
            <horizontal_fov>1.0856</horizontal_fov>
            <image>
              <width>640</width>
              <height>480</height>
              <format>R8G8B8</format>
            </image>
            <clip>
              <near>0.03</near>
              <far>100</far>
            </clip>
          </camera>
          <plugin name='camera_controller' filename='libgazebo_ros_camera.so'>
            <alwaysOn>1</alwaysOn>
            <updateRate>30.0</updateRate>
            <cameraName>top_right_camera</cameraName>
            <frameName>top_right_camera_rgb_optical_frame</frameName>
            <imageTopicName>image_raw</imageTopicName>
            <cameraInfoTopicName>camera_info</cameraInfoTopicName>
            <hackBaseline>0.07</hackBaseline>
            <distortionK1>0.0</distortionK1>
            <distortionK2>0.0</distortionK2>
            <distortionK3>0.0</distortionK3>
            <distortionT1>0.0</distortionT1>
            <distortionT2>0.0</distortionT2>
            <robotNamespace>/</robotNamespace>
          </plugin>
          <pose>-0.28 -0.025 0.7 0 -0.3 -0.7854</pose>
        </sensor>
        <self_collide>0</self_collide>
        <enable_wind>0</enable_wind>
        <kinematic>0</kinematic>
      </link>
      <joint name='front_left_steer_joint' type='revolute'>
        <pose relative_to='base_footprint'>0.15 -0.175 0.08 0 -0 0</pose>
        <parent>base_footprint</parent>
        <child>front_left_steer_link</child>
        <axis>
          <xyz>0 0 1</xyz>
          <limit>
            <lower>-3.14159</lower>
            <upper>3.14159</upper>
            <effort>15</effort>
            <velocity>5</velocity>
          </limit>
          <dynamics>
            <damping>0</damping>
            <friction>0</friction>
            <spring_reference>0</spring_reference>
            <spring_stiffness>0</spring_stiffness>
          </dynamics>
        </axis>
      </joint>
      <link name='front_left_steer_link'>
        <pose relative_to='front_left_steer_joint'>0 0 0 0 -0 0</pose>
        <inertial>
          <pose>0 0 0 0 -0 0</pose>
          <mass>0.5</mass>
          <inertia>
            <ixx>0.000492667</ixx>
            <ixy>0</ixy>
            <ixz>0</ixz>
            <iyy>0.000492667</iyy>
            <iyz>0</iyz>
            <izz>0.0009</izz>
          </inertia>
        </inertial>
        <collision name='front_left_steer_link_collision'>
          <pose>0 0 0 0 -0 0</pose>
          <geometry>
            <cylinder>
              <length>0.02</length>
              <radius>0.05</radius>
            </cylinder>
          </geometry>
          <max_contacts>10</max_contacts>
          <surface>
            <contact>
              <ode/>
            </contact>
            <bounce/>
            <friction>
              <torsional>
                <ode/>
              </torsional>
              <ode/>
            </friction>
          </surface>
        </collision>
        <self_collide>0</self_collide>
        <enable_wind>0</enable_wind>
        <kinematic>0</kinematic>
      </link>
      <joint name='front_left_wheel_joint' type='revolute'>
        <pose relative_to='front_left_steer_link'>0 0 -0.08 -1.5708 0 1.5708</pose>
        <parent>front_left_steer_link</parent>
        <child>front_left_wheel_link</child>
        <axis>
          <xyz>1 0 0</xyz>
          <limit>
            <lower>-1e+16</lower>
            <upper>1e+16</upper>
          </limit>
          <dynamics>
            <damping>0</damping>
            <friction>0</friction>
            <spring_reference>0</spring_reference>
            <spring_stiffness>0</spring_stiffness>
          </dynamics>
        </axis>
      </joint>
      <link name='front_left_wheel_link'>
        <pose relative_to='front_left_wheel_joint'>0 0 0 0 -0 0</pose>
        <inertial>
          <pose>0 0 0 0 -0 0</pose>
          <mass>0.5</mass>
          <inertia>
            <ixx>0.000492667</ixx>
            <ixy>0</ixy>
            <ixz>0</ixz>
            <iyy>0.000492667</iyy>
            <iyz>0</iyz>
            <izz>0.0009</izz>
          </inertia>
        </inertial>
        <collision name='front_left_wheel_link_collision'>
          <pose>0 0 0 -1.5708 0 1.5708</pose>
          <geometry>
            <cylinder>
              <length>0.032</length>
              <radius>0.06</radius>
            </cylinder>
          </geometry>
          <max_contacts>10</max_contacts>
          <surface>
            <contact>
              <ode/>
            </contact>
            <bounce/>
            <friction>
              <torsional>
                <ode/>
              </torsional>
              <ode/>
            </friction>
          </surface>
        </collision>
        <visual name='front_left_wheel_link_visual'>
          <pose>0 0.06 0.06 -1.57079 1.57079 3.14159</pose>
          <geometry>
            <mesh>
              <scale>1 1 1</scale>
              <uri>file:////home/nel/catkin_ws/src/AutoMec-AD/prometheus_description/meshes/wheel.dae</uri>
            </mesh>
          </geometry>
        </visual>
        <self_collide>0</self_collide>
        <enable_wind>0</enable_wind>
        <kinematic>0</kinematic>
      </link>
      <joint name='front_right_steer_joint' type='revolute'>
        <pose relative_to='base_footprint'>0.15 0.175 0.08 0 -0 0</pose>
        <parent>base_footprint</parent>
        <child>front_right_steer_link</child>
        <axis>
          <xyz>0 0 1</xyz>
          <limit>
            <lower>-3.14159</lower>
            <upper>3.14159</upper>
            <effort>15</effort>
            <velocity>5</velocity>
          </limit>
          <dynamics>
            <damping>0</damping>
            <friction>0</friction>
            <spring_reference>0</spring_reference>
            <spring_stiffness>0</spring_stiffness>
          </dynamics>
        </axis>
      </joint>
      <link name='front_right_steer_link'>
        <pose relative_to='front_right_steer_joint'>0 0 0 0 -0 0</pose>
        <inertial>
          <pose>0 0 0 0 -0 0</pose>
          <mass>0.5</mass>
          <inertia>
            <ixx>0.000492667</ixx>
            <ixy>0</ixy>
            <ixz>0</ixz>
            <iyy>0.000492667</iyy>
            <iyz>0</iyz>
            <izz>0.0009</izz>
          </inertia>
        </inertial>
        <collision name='front_right_steer_link_collision'>
          <pose>0 0 0 0 -0 0</pose>
          <geometry>
            <cylinder>
              <length>0.02</length>
              <radius>0.05</radius>
            </cylinder>
          </geometry>
          <max_contacts>10</max_contacts>
          <surface>
            <contact>
              <ode/>
            </contact>
            <bounce/>
            <friction>
              <torsional>
                <ode/>
              </torsional>
              <ode/>
            </friction>
          </surface>
        </collision>
        <self_collide>0</self_collide>
        <enable_wind>0</enable_wind>
        <kinematic>0</kinematic>
      </link>
      <joint name='front_right_wheel_joint' type='revolute'>
        <pose relative_to='front_right_steer_link'>0 0 -0.08 -1.5708 -0 -1.5708</pose>
        <parent>front_right_steer_link</parent>
        <child>front_right_wheel_link</child>
        <axis>
          <xyz>-1 0 0</xyz>
          <limit>
            <lower>-1e+16</lower>
            <upper>1e+16</upper>
          </limit>
          <dynamics>
            <damping>0</damping>
            <friction>0</friction>
            <spring_reference>0</spring_reference>
            <spring_stiffness>0</spring_stiffness>
          </dynamics>
        </axis>
      </joint>
      <link name='front_right_wheel_link'>
        <pose relative_to='front_right_wheel_joint'>0 0 0 0 -0 0</pose>
        <inertial>
          <pose>0 0 0 0 -0 0</pose>
          <mass>0.5</mass>
          <inertia>
            <ixx>0.000492667</ixx>
            <ixy>0</ixy>
            <ixz>0</ixz>
            <iyy>0.000492667</iyy>
            <iyz>0</iyz>
            <izz>0.0009</izz>
          </inertia>
        </inertial>
        <collision name='front_right_wheel_link_collision'>
          <pose>0 0 0 -1.5708 -0 -1.5708</pose>
          <geometry>
            <cylinder>
              <length>0.032</length>
              <radius>0.06</radius>
            </cylinder>
          </geometry>
          <max_contacts>10</max_contacts>
          <surface>
            <contact>
              <ode/>
            </contact>
            <bounce/>
            <friction>
              <torsional>
                <ode/>
              </torsional>
              <ode/>
            </friction>
          </surface>
        </collision>
        <visual name='front_right_wheel_link_visual'>
          <pose>0 0.06 0.06 -1.57079 1.57079 3.14159</pose>
          <geometry>
            <mesh>
              <scale>1 1 1</scale>
              <uri>file:////home/nel/catkin_ws/src/AutoMec-AD/prometheus_description/meshes/wheel.dae</uri>
            </mesh>
          </geometry>
        </visual>
        <self_collide>0</self_collide>
        <enable_wind>0</enable_wind>
        <kinematic>0</kinematic>
      </link>
      <joint name='front_steer_joint' type='revolute'>
        <pose relative_to='base_footprint'>-0.2 0 0.08 0 -0 0</pose>
        <parent>base_footprint</parent>
        <child>front_steer_link</child>
        <axis>
          <xyz>0 0 1</xyz>
          <limit>
            <lower>-3.14159</lower>
            <upper>3.14159</upper>
            <effort>15</effort>
            <velocity>5</velocity>
          </limit>
          <dynamics>
            <damping>0</damping>
            <friction>0</friction>
            <spring_reference>0</spring_reference>
            <spring_stiffness>0</spring_stiffness>
          </dynamics>
        </axis>
      </joint>
      <link name='front_steer_link'>
        <pose relative_to='front_steer_joint'>0 0 0 0 -0 0</pose>
        <inertial>
          <pose>0 0 0 0 -0 0</pose>
          <mass>0.5</mass>
          <inertia>
            <ixx>0.000492667</ixx>
            <ixy>0</ixy>
            <ixz>0</ixz>
            <iyy>0.000492667</iyy>
            <iyz>0</iyz>
            <izz>0.0009</izz>
          </inertia>
        </inertial>
        <collision name='front_steer_link_collision'>
          <pose>0 0 0 0 -0 0</pose>
          <geometry>
            <cylinder>
              <length>0.02</length>
              <radius>0.05</radius>
            </cylinder>
          </geometry>
          <surface>
            <contact>
              <ode/>
            </contact>
            <friction>
              <ode/>
              <torsional>
                <ode/>
              </torsional>
            </friction>
            <bounce/>
          </surface>
          <max_contacts>10</max_contacts>
        </collision>
        <self_collide>0</self_collide>
        <enable_wind>0</enable_wind>
        <kinematic>0</kinematic>
      </link>
      <joint name='rear_left_wheel_joint' type='revolute'>
        <pose relative_to='base_footprint'>-0.15 -0.175 0 -1.5708 0 1.5708</pose>
        <parent>base_footprint</parent>
        <child>rear_left_wheel_link</child>
        <axis>
          <xyz>1 0 0</xyz>
          <limit>
            <lower>-1e+16</lower>
            <upper>1e+16</upper>
          </limit>
          <dynamics>
            <damping>0</damping>
            <friction>0</friction>
            <spring_reference>0</spring_reference>
            <spring_stiffness>0</spring_stiffness>
          </dynamics>
        </axis>
      </joint>
      <link name='rear_left_wheel_link'>
        <pose relative_to='rear_left_wheel_joint'>0 0 0 0 -0 0</pose>
        <inertial>
          <pose>0 0 0 0 -0 0</pose>
          <mass>0.5</mass>
          <inertia>
            <ixx>0.000492667</ixx>
            <ixy>0</ixy>
            <ixz>0</ixz>
            <iyy>0.000492667</iyy>
            <iyz>0</iyz>
            <izz>0.0009</izz>
          </inertia>
        </inertial>
        <collision name='rear_left_wheel_link_collision'>
          <pose>0 0 0 -1.5708 0 1.5708</pose>
          <geometry>
            <cylinder>
              <length>0.032</length>
              <radius>0.06</radius>
            </cylinder>
          </geometry>
          <max_contacts>10</max_contacts>
          <surface>
            <contact>
              <ode/>
            </contact>
            <bounce/>
            <friction>
              <torsional>
                <ode/>
              </torsional>
              <ode/>
            </friction>
          </surface>
        </collision>
        <visual name='rear_left_wheel_link_visual'>
          <pose>0 0.06 0.06 -1.57079 1.57079 3.14159</pose>
          <geometry>
            <mesh>
              <scale>1 1 1</scale>
              <uri>file:////home/nel/catkin_ws/src/AutoMec-AD/prometheus_description/meshes/wheel.dae</uri>
            </mesh>
          </geometry>
        </visual>
        <self_collide>0</self_collide>
        <enable_wind>0</enable_wind>
        <kinematic>0</kinematic>
      </link>
      <joint name='rear_right_wheel_joint' type='revolute'>
        <pose relative_to='base_footprint'>-0.15 0.175 0 -1.5708 -0 -1.5708</pose>
        <parent>base_footprint</parent>
        <child>rear_right_wheel_link</child>
        <axis>
          <xyz>-1 0 0</xyz>
          <limit>
            <lower>-1e+16</lower>
            <upper>1e+16</upper>
          </limit>
          <dynamics>
            <damping>0</damping>
            <friction>0</friction>
            <spring_reference>0</spring_reference>
            <spring_stiffness>0</spring_stiffness>
          </dynamics>
        </axis>
      </joint>
      <link name='rear_right_wheel_link'>
        <pose relative_to='rear_right_wheel_joint'>0 0 0 0 -0 0</pose>
        <inertial>
          <pose>0 0 0 0 -0 0</pose>
          <mass>0.5</mass>
          <inertia>
            <ixx>0.000492667</ixx>
            <ixy>0</ixy>
            <ixz>0</ixz>
            <iyy>0.000492667</iyy>
            <iyz>0</iyz>
            <izz>0.0009</izz>
          </inertia>
        </inertial>
        <collision name='rear_right_wheel_link_collision'>
          <pose>0 0 0 -1.5708 -0 -1.5708</pose>
          <geometry>
            <cylinder>
              <length>0.032</length>
              <radius>0.06</radius>
            </cylinder>
          </geometry>
          <max_contacts>10</max_contacts>
          <surface>
            <contact>
              <ode/>
            </contact>
            <bounce/>
            <friction>
              <torsional>
                <ode/>
              </torsional>
              <ode/>
            </friction>
          </surface>
        </collision>
        <visual name='rear_right_wheel_link_visual'>
          <pose>0 0.06 0.06 -1.57079 1.57079 3.14159</pose>
          <geometry>
            <mesh>
              <scale>1 1 1</scale>
              <uri>file:////home/nel/catkin_ws/src/AutoMec-AD/prometheus_description/meshes/wheel.dae</uri>
            </mesh>
          </geometry>
        </visual>
        <self_collide>0</self_collide>
        <enable_wind>0</enable_wind>
        <kinematic>0</kinematic>
      </link>
      <joint name='rear_wheel_joint' type='revolute'>
        <pose relative_to='base_footprint'>0.2 0 0 -1.5708 -0 -1.5708</pose>
        <parent>base_footprint</parent>
        <child>rear_wheel_link</child>
        <axis>
          <xyz>1 0 0</xyz>
          <limit>
            <lower>-1e+16</lower>
            <upper>1e+16</upper>
          </limit>
          <dynamics>
            <damping>0</damping>
            <friction>0</friction>
            <spring_reference>0</spring_reference>
            <spring_stiffness>0</spring_stiffness>
          </dynamics>
        </axis>
      </joint>
      <link name='rear_wheel_link'>
        <pose relative_to='rear_wheel_joint'>0 0 0 0 -0 0</pose>
        <inertial>
          <pose>0 0 0 0 -0 0</pose>
          <mass>0.5</mass>
          <inertia>
            <ixx>0.000492667</ixx>
            <ixy>0</ixy>
            <ixz>0</ixz>
            <iyy>0.000492667</iyy>
            <iyz>0</iyz>
            <izz>0.0009</izz>
          </inertia>
        </inertial>
        <collision name='rear_wheel_link_collision'>
          <pose>0 0 0 0 -0 0</pose>
          <geometry>
            <cylinder>
              <length>0.00032</length>
              <radius>0.0006</radius>
            </cylinder>
          </geometry>
          <max_contacts>10</max_contacts>
          <surface>
            <contact>
              <ode/>
            </contact>
            <bounce/>
            <friction>
              <torsional>
                <ode/>
              </torsional>
              <ode/>
            </friction>
          </surface>
        </collision>
        <self_collide>0</self_collide>
        <enable_wind>0</enable_wind>
        <kinematic>0</kinematic>
      </link>
      <static>0</static>
      <plugin name='gazebo_ros_control' filename='libgazebo_ros_control.so'>
        <robotSimType>steer_bot_hardware_gazebo/SteerBotHardwareGazebo</robotSimType>
        <robotNamespace>/</robotNamespace>
      </plugin>
      <pose>-0.7 -0.5 0 0 -0 0</pose>
    </model>
    <state world_name='default'>
      <sim_time>982 69000000</sim_time>
      <real_time>1236 837079907</real_time>
      <wall_time>1673982848 1486156</wall_time>
      <iterations>982069</iterations>
      <model name='Bus_signal'>
        <pose>4.17555 2.13758 0.025 -3e-06 -0 1.5e-05</pose>
        <scale>1 1 1</scale>
        <link name='pictogram'>
          <pose>4.17555 2.11509 0.775 -3e-06 -0 1.5e-05</pose>
          <velocity>-0 -0.000642 -0.000101 0.000828 0 -3e-06</velocity>
          <acceleration>-0.000494 -0.643938 -0.101856 0.830868 -3.5e-05 -0.005237</acceleration>
          <wrench>-0.000494 -0.643938 -0.101856 0 -0 0</wrench>
        </link>
        <link name='support_structure'>
          <pose>4.17555 2.13758 0.025 -3e-06 -0 1.5e-05</pose>
          <velocity>-0 -2.1e-05 -8.3e-05 0.000834 -0 -1e-06</velocity>
          <acceleration>-0.000313 -0.020743 -0.082929 0.829258 -3.2e-05 -0.003061</acceleration>
          <wrench>-0.000313 -0.020743 -0.082929 0 -0 0</wrench>
        </link>
      </model>
      <model name='Bus_signal_0'>
        <pose>-6.4414 2.30952 0.025 -5e-06 -0 0.042961</pose>
        <scale>1 1 1</scale>
        <link name='pictogram'>
          <pose>-6.44044 2.28705 0.775 -5e-06 -0 0.042961</pose>
          <velocity>-4e-05 0.000942 0.000153 -0.001215 -5.2e-05 -1e-06</velocity>
          <acceleration>0.027696 -0.62149 -0.43559 0.801805 0.034553 0.000141</acceleration>
          <wrench>0.027696 -0.62149 -0.43559 0 -0 0</wrench>
        </link>
        <link name='support_structure'>
          <pose>-6.4414 2.30952 0.025 -5e-06 -0 0.042961</pose>
          <velocity>-1e-06 3e-05 0.000121 -0.001205 -5.2e-05 1e-06</velocity>
          <acceleration>0.001467 -0.020028 -0.431825 0.798006 0.034385 0.005922</acceleration>
          <wrench>0.001467 -0.020028 -0.431825 0 -0 0</wrench>
        </link>
      </model>
      <model name='Cattle_signal'>
        <pose>3.38048 4.96081 0.025001 6e-06 -0 2.36912</pose>
        <scale>1 1 1</scale>
        <link name='pictogram'>
          <pose>3.39618 4.97693 0.775 6e-06 -0 2.36912</pose>
          <velocity>0.001664 0.001708 0.00089 -0.002203 0.002147 1e-06</velocity>
          <acceleration>-0.408713 -0.418609 1.35958 0.540807 -0.527065 0.007328</acceleration>
          <wrench>-0.408713 -0.418609 1.35958 0 -0 0</wrench>
        </link>
        <link name='support_structure'>
          <pose>3.38048 4.96081 0.025001 6e-06 -0 2.36912</pose>
          <velocity>5.3e-05 5.5e-05 0.000974 -0.002193 0.002137 -5e-06</velocity>
          <acceleration>-0.013722 -0.013323 1.35692 0.552493 -0.53845 -0.004071</acceleration>
          <wrench>-0.013722 -0.013323 1.35692 0 -0 0</wrench>
        </link>
      </model>
      <model name='Cattle_signal_0'>
        <pose>-7.67169 4.50176 0.025001 1.2e-05 -0 2.26712</pose>
        <scale>1 1 1</scale>
        <link name='pictogram'>
          <pose>-7.65443 4.5162 0.775 1.2e-05 -0 2.26712</pose>
          <velocity>5.9e-05 4.9e-05 8e-06 -6.4e-05 7.6e-05 -3e-06</velocity>
          <acceleration>-0.395559 -0.330393 -0.051586 0.426512 -0.510224 -0.006059</acceleration>
          <wrench>-0.395559 -0.330393 -0.051586 0 -0 0</wrench>
        </link>
        <link name='support_structure'>
          <pose>-7.67169 4.50176 0.025001 1.2e-05 -0 2.26712</pose>
          <velocity>2e-06 2e-06 9e-06 -6.1e-05 7.3e-05 -1e-06</velocity>
          <acceleration>-0.012878 -0.010481 -0.066392 0.425812 -0.509385 -0.002174</acceleration>
          <wrench>-0.012878 -0.010481 -0.066392 0 -0 0</wrench>
        </link>
      </model>
      <model name='Crosswalk_signal'>
        <pose>7.71611 4.58225 0.025 2e-06 0 0.773011</pose>
        <scale>1 1 1</scale>
        <link name='pictogram'>
          <pose>7.73182 4.56614 0.775 2e-06 0 0.773011</pose>
          <velocity>-0.001228 0.001259 -0.000176 -0.001624 -0.001584 5e-06</velocity>
          <acceleration>-0.359925 0.368723 -0.051539 -0.475894 -0.464287 0.009234</acceleration>
          <wrench>-0.359925 0.368723 -0.051539 0 -0 0</wrench>
        </link>
        <link name='support_structure'>
          <pose>7.71611 4.58225 0.025 2e-06 0 0.773011</pose>
          <velocity>-4e-05 4.1e-05 -0.000227 -0.001626 -0.001586 1e-06</velocity>
          <acceleration>-0.011704 0.011785 -0.066422 -0.475438 -0.46384 0.001477</acceleration>
          <wrench>-0.011704 0.011785 -0.066422 0 -0 0</wrench>
        </link>
      </model>
      <model name='Crosswalk_signal_0'>
        <pose>-7.99384 -0.037584 0.025 -0 -0 -2.81151</pose>
        <scale>1 1 1</scale>
        <link name='pictogram'>
          <pose>-8.00113 -0.016298 0.774999 -0 -0 -2.81151</pose>
          <velocity>0.00055 -0.001604 -0.00017 0.00207 0.000709 4e-06</velocity>
          <acceleration>0.167201 -0.487437 -0.051543 0.629005 0.215538 0.008444</acceleration>
          <wrench>0.167201 -0.487437 -0.051543 0 -0 0</wrench>
        </link>
        <link name='support_structure'>
          <pose>-7.99384 -0.037584 0.025 -0 -0 -2.81151</pose>
          <velocity>1.8e-05 -5.2e-05 -0.000219 0.002072 0.00071 1e-06</velocity>
          <acceleration>0.005546 -0.01566 -0.066416 0.628291 0.215292 0.001686</acceleration>
          <wrench>0.005546 -0.01566 -0.066416 0 -0 0</wrench>
        </link>
      </model>
      <model name='Depression_signal'>
        <pose>5.39491 5.52739 0.025 -5e-06 0 1.58697</pose>
        <scale>1 1 1</scale>
        <link name='pictogram'>
          <pose>5.4174 5.52775 0.775 -5e-06 0 1.58697</pose>
          <velocity>0.000373 6e-06 -5.9e-05 -8e-06 0.000482 3e-06</velocity>
          <acceleration>0.64387 0.010942 -0.101873 -0.013491 0.830781 0.005225</acceleration>
          <wrench>0.64387 0.010942 -0.101873 0 -0 0</wrench>
        </link>
        <link name='support_structure'>
          <pose>5.39491 5.52739 0.025 -5e-06 0 1.58697</pose>
          <velocity>1.2e-05 0 -4.9e-05 -8e-06 0.000489 1e-06</velocity>
          <acceleration>0.02074 0.000664 -0.082922 -0.013461 0.829096 0.003179</acceleration>
          <wrench>0.02074 0.000664 -0.082922 0 -0 0</wrench>
        </link>
      </model>
      <model name='Depression_signal_0'>
        <pose>-8.81456 1.5445 0.025001 1e-05 -0 3.13187</pose>
        <scale>1 1 1</scale>
        <link name='pictogram'>
          <pose>-8.81434 1.567 0.775 1e-05 -0 3.13187</pose>
          <velocity>1e-05 0.00101 0.000101 -0.001303 1.3e-05 2e-06</velocity>
          <acceleration>-0.004663 -0.515569 -0.051664 0.66522 -0.006426 0.001959</acceleration>
          <wrench>-0.004663 -0.515569 -0.051664 0 -0 0</wrench>
        </link>
        <link name='support_structure'>
          <pose>-8.81456 1.5445 0.025001 1e-05 -0 3.13187</pose>
          <velocity>0 3.2e-05 0.00013 -0.001296 1.3e-05 1e-06</velocity>
          <acceleration>0.000175 -0.016607 -0.066355 0.663512 -0.006411 0.003294</acceleration>
          <wrench>0.000175 -0.016607 -0.066355 0 -0 0</wrench>
        </link>
      </model>
      <model name='Hospital_signal'>
        <pose>2.036 3.03403 0.025001 -5e-06 -0 2.80511</pose>
        <scale>1 1 1</scale>
        <link name='pictogram'>
          <pose>2.04343 3.05527 0.775 -5e-06 -0 2.80511</pose>
          <velocity>-0.000675 -0.001932 0.000803 0.002493 -0.000872 0</velocity>
          <acceleration>0.237524 0.676689 1.07902 -0.873695 0.305658 0.005446</acceleration>
          <wrench>0.237524 0.676689 1.07902 0 -0 0</wrench>
        </link>
        <link name='support_structure'>
          <pose>2.036 3.03403 0.025001 -5e-06 -0 2.80511</pose>
          <velocity>-2.1e-05 -6.2e-05 0.000755 0.002479 -0.000867 -5e-06</velocity>
          <acceleration>0.008211 0.021905 1.11156 -0.888977 0.310999 -0.004205</acceleration>
          <wrench>0.008211 0.021905 1.11156 0 -0 0</wrench>
        </link>
      </model>
      <model name='Hospital_signal_0'>
        <pose>-5.64693 5.55419 0.025 0 -0 1.57191</pose>
        <scale>1 1 1</scale>
        <link name='pictogram'>
          <pose>-5.62443 5.55421 0.775 0 -0 1.57191</pose>
          <velocity>1.3e-05 0.000432 8e-05 -0.000557 1.8e-05 8e-06</velocity>
          <acceleration>-0.003355 0.863382 0.159608 -1.11422 -0.00185 0.000857</acceleration>
          <wrench>-0.003355 0.863382 0.159608 0 -0 0</wrench>
        </link>
        <link name='support_structure'>
          <pose>-5.64693 5.55419 0.025 0 -0 1.57191</pose>
          <velocity>-0 1.4e-05 8.2e-05 -0.000569 1.8e-05 5e-06</velocity>
          <acceleration>-0.001644 0.0282 0.163221 -1.13748 -0.001299 -0.000736</acceleration>
          <wrench>-0.001644 0.0282 0.163221 0 -0 0</wrench>
        </link>
      </model>
      <model name='Lights_signal'>
        <pose>7.38337 -0.697613 0.025 3e-06 -0 -1.11442</pose>
        <scale>1 1 1</scale>
        <link name='pictogram'>
          <pose>7.36317 -0.707529 0.775 3e-06 -0 -1.11442</pose>
          <velocity>-0.001241 -0.000609 0.000393 0.000786 -0.0016 0</velocity>
          <acceleration>0.493399 0.242861 0.697916 -0.312865 0.637159 -0.004862</acceleration>
          <wrench>0.493399 0.242861 0.697916 0 -0 0</wrench>
        </link>
        <link name='support_structure'>
          <pose>7.38337 -0.697613 0.025 3e-06 -0 -1.11442</pose>
          <velocity>-4e-05 -1.9e-05 0.00044 0.00078 -0.00159 4e-06</velocity>
          <acceleration>0.015933 0.008387 0.6897 -0.320022 0.651743 0.003315</acceleration>
          <wrench>0.015933 0.008387 0.6897 0 -0 0</wrench>
        </link>
      </model>
      <model name='Lights_signal_0'>
        <pose>-3.38551 4.96533 0.025002 2.4e-05 -0 0.905168</pose>
        <scale>1 1 1</scale>
        <link name='pictogram'>
          <pose>-3.3678 4.95142 0.775001 2.4e-05 -0 0.905168</pose>
          <velocity>-0.00011 8.6e-05 -1.4e-05 -0.000112 -0.000142 5e-06</velocity>
          <acceleration>-0.405322 0.318046 -0.051559 -0.410517 -0.522887 0.009545</acceleration>
          <wrench>-0.405322 0.318046 -0.051559 0 -0 0</wrench>
        </link>
        <link name='support_structure'>
          <pose>-3.38551 4.96533 0.025002 2.4e-05 -0 0.905168</pose>
          <velocity>-4e-06 3e-06 -1.8e-05 -0.000113 -0.000144 1e-06</velocity>
          <acceleration>-0.013149 0.010144 -0.066418 -0.410152 -0.52242 0.001408</acceleration>
          <wrench>-0.013149 0.010144 -0.066418 0 -0 0</wrench>
        </link>
      </model>
      <model name='Other_Dangers_signal'>
        <pose>3.51019 -1.14651 0.025 0 -1e-06 -1.61764</pose>
        <scale>1 1 1</scale>
        <link name='pictogram'>
          <pose>3.48772 -1.14545 0.774999 0 -1e-06 -1.61764</pose>
          <velocity>5e-06 0.000432 -8e-05 -0.000557 7e-06 7e-06</velocity>
          <acceleration>0.017084 0.868318 -0.160809 -1.12138 0.021469 0.019701</acceleration>
          <wrench>0.017084 0.868318 -0.160809 0 -0 0</wrench>
        </link>
        <link name='support_structure'>
          <pose>3.51019 -1.14651 0.025 0 -1e-06 -1.61764</pose>
          <velocity>-1e-06 1.4e-05 -8.1e-05 -0.000569 8e-06 6e-06</velocity>
          <acceleration>0.000696 0.028302 -0.163858 -1.14504 0.021681 0.015568</acceleration>
          <wrench>0.000696 0.028302 -0.163858 0 -0 0</wrench>
        </link>
      </model>
      <model name='Other_Dangers_signal_0'>
        <pose>-5.1248 1.04292 0.025 3e-06 -0 1.47794</pose>
        <scale>1 1 1</scale>
        <link name='pictogram'>
          <pose>-5.10239 1.04083 0.775 3e-06 -0 1.47794</pose>
          <velocity>-0.000256 2.4e-05 -2.6e-05 -3.1e-05 -0.000331 -2e-06</velocity>
          <acceleration>-0.513285 0.048112 -0.051588 -0.061718 -0.66231 -0.003522</acceleration>
          <wrench>-0.513285 0.048112 -0.051588 0 -0 0</wrench>
        </link>
        <link name='support_structure'>
          <pose>-5.1248 1.04292 0.025 3e-06 -0 1.47794</pose>
          <velocity>-8e-06 1e-06 -3.4e-05 -3.1e-05 -0.000337 -1e-06</velocity>
          <acceleration>-0.016509 0.001835 -0.066371 -0.06158 -0.660842 -0.002879</acceleration>
          <wrench>-0.016509 0.001835 -0.066371 0 -0 0</wrench>
        </link>
      </model>
      <model name='Park_signal'>
        <pose>0.80939 -1.1885 0.025001 5e-06 -0 -1.65941</pose>
        <scale>1 1 1</scale>
        <link name='pictogram'>
          <pose>0.786975 -1.1865 0.775 5e-06 -0 -1.65941</pose>
          <velocity>0.000622 -5.5e-05 -6.2e-05 7.1e-05 0.000803 4e-06</velocity>
          <acceleration>0.513383 -0.045382 -0.051573 0.05882 0.662399 0.006509</acceleration>
          <wrench>0.513383 -0.045382 -0.051573 0 -0 0</wrench>
        </link>
        <link name='support_structure'>
          <pose>0.80939 -1.1885 0.025001 5e-06 -0 -1.65941</pose>
          <velocity>2e-05 -2e-06 -8.1e-05 7.2e-05 0.000807 1e-06</velocity>
          <acceleration>0.016557 -0.001253 -0.066397 0.05873 0.66137 0.002111</acceleration>
          <wrench>0.016557 -0.001253 -0.066397 0 -0 0</wrench>
        </link>
      </model>
      <model name='Park_signal_0'>
        <pose>-3.13415 -1.2839 0.025 0 -1e-06 -1.5078</pose>
        <scale>1 1 1</scale>
        <link name='pictogram'>
          <pose>-3.1566 -1.28531 0.774999 0 -1e-06 -1.5078</pose>
          <velocity>-8e-06 0.000437 -8.1e-05 -0.000564 -1e-05 -1e-06</velocity>
          <acceleration>-0.021709 0.869276 -0.160575 -1.1215 -0.027161 -0.008929</acceleration>
          <wrench>-0.021709 0.869276 -0.160575 0 -0 0</wrench>
        </link>
        <link name='support_structure'>
          <pose>-3.13415 -1.2839 0.025 0 -1e-06 -1.5078</pose>
          <velocity>-0 1.4e-05 -8.3e-05 -0.000576 -1.1e-05 -1e-06</velocity>
          <acceleration>-0.001206 0.02847 -0.16517 -1.14474 -0.027583 -0.005829</acceleration>
          <wrench>-0.001206 0.02847 -0.16517 0 -0 0</wrench>
        </link>
      </model>
      <model name='RMV_Signal'>
        <pose>6.44133 1.97575 0.025001 1.3e-05 -0 3.0593</pose>
        <scale>1 1 1</scale>
        <link name='pictogram'>
          <pose>6.44318 1.99818 0.775 1.3e-05 -0 3.0593</pose>
          <velocity>-6.6e-05 -0.000802 -8e-05 0.001036 -8.5e-05 -5e-06</velocity>
          <acceleration>-0.042531 -0.513511 -0.051548 0.662601 -0.054677 -0.008854</acceleration>
          <wrench>-0.042531 -0.513511 -0.051548 0 -0 0</wrench>
        </link>
        <link name='support_structure'>
          <pose>6.44133 1.97575 0.025001 1.3e-05 -0 3.0593</pose>
          <velocity>-2e-06 -2.6e-05 -0.000104 0.001038 -8.6e-05 -1e-06</velocity>
          <acceleration>-0.00153 -0.01654 -0.066415 0.661904 -0.054619 -0.001617</acceleration>
          <wrench>-0.00153 -0.01654 -0.066415 0 -0 0</wrench>
        </link>
      </model>
      <model name='RMV_Signal_0'>
        <pose>-5.12761 3.22873 0.025 -0 -0 -1.65765</pose>
        <scale>1 1 1</scale>
        <link name='pictogram'>
          <pose>-5.15003 3.23068 0.775 -0 -0 -1.65765</pose>
          <velocity>4.6e-05 0.000434 8.1e-05 -0.000561 6.1e-05 1.3e-05</velocity>
          <acceleration>0.063888 0.871593 0.161768 -1.12474 0.08484 0.011391</acceleration>
          <wrench>0.063888 0.871593 0.161768 0 -0 0</wrench>
        </link>
        <link name='support_structure'>
          <pose>-5.12761 3.22873 0.025 -0 -0 -1.65765</pose>
          <velocity>0 1.4e-05 8.3e-05 -0.000573 6.3e-05 1e-05</velocity>
          <acceleration>0.000835 0.028612 0.165804 -1.14821 0.087316 0.008725</acceleration>
          <wrench>0.000835 0.028612 0.165804 0 -0 0</wrench>
        </link>
      </model>
      <model name='Road_Narrow_signal'>
        <pose>4.75557 0.988519 0.025 0 1e-06 1.51992</pose>
        <scale>1 1 1</scale>
        <link name='pictogram'>
          <pose>4.77804 0.987375 0.775 0 1e-06 1.51992</pose>
          <velocity>-9e-06 -3.5e-05 0.000332 4.5e-05 -1e-05 -1.1e-05</velocity>
          <acceleration>-0.071619 -0.926456 0.506829 1.19625 -0.088318 0.000943</acceleration>
          <wrench>-0.071619 -0.926456 0.506829 0 -0 0</wrench>
        </link>
        <link name='support_structure'>
          <pose>4.75557 0.988519 0.025 0 1e-06 1.51992</pose>
          <velocity>-1e-06 -1e-06 0.000338 5.9e-05 -1e-05 -8e-06</velocity>
          <acceleration>-0.005026 -0.030017 0.513227 1.22177 -0.088723 0.002615</acceleration>
          <wrench>-0.005026 -0.030017 0.513227 0 -0 0</wrench>
        </link>
      </model>
      <model name='Road_Narrow_signal_0'>
        <pose>-4.08803 1.4013 0.025001 7e-06 0 -2.9787</pose>
        <scale>1 1 1</scale>
        <link name='pictogram'>
          <pose>-4.09168 1.42351 0.775 7e-06 0 -2.9787</pose>
          <velocity>4.7e-05 -0.000286 -2.9e-05 0.00037 6.1e-05 3e-06</velocity>
          <acceleration>0.08385 -0.508584 -0.051559 0.656271 0.107893 0.005006</acceleration>
          <wrench>0.08385 -0.508584 -0.051559 0 -0 0</wrench>
        </link>
        <link name='support_structure'>
          <pose>-4.08803 1.4013 0.025001 7e-06 0 -2.9787</pose>
          <velocity>2e-06 -9e-06 -3.8e-05 0.000374 6.2e-05 1e-06</velocity>
          <acceleration>0.002935 -0.016345 -0.066383 0.655045 0.10769 0.002408</acceleration>
          <wrench>0.002935 -0.016345 -0.066383 0 -0 0</wrench>
        </link>
      </model>
      <model name='Round_About_signal'>
        <pose>8.5948 1.97851 0.025 -1e-06 0 -7.1e-05</pose>
        <scale>1 1 1</scale>
        <link name='pictogram'>
          <pose>8.5948 1.95601 0.774999 0 0 -7.1e-05</pose>
          <velocity>0 0.000554 -5.5e-05 -0.000715 -0 -1e-06</velocity>
          <acceleration>0.000504 0.51278 -0.104741 -0.661529 0.000102 -0.0037</acceleration>
          <wrench>0.000504 0.51278 -0.104741 0 -0 0</wrench>
        </link>
        <link name='support_structure'>
          <pose>8.5948 1.97851 0.025 -1e-06 0 -7.1e-05</pose>
          <velocity>0 1.8e-05 -7.2e-05 -0.000721 -0 -1e-06</velocity>
          <acceleration>0.00045 0.016571 -0.122165 -0.659816 0.0001 -0.004393</acceleration>
          <wrench>0.00045 0.016571 -0.122165 0 -0 0</wrench>
        </link>
      </model>
      <model name='Round_About_signal_0'>
        <pose>-2.39073 3.51649 0.025 0 -0 0.544288</pose>
        <scale>1 1 1</scale>
        <link name='pictogram'>
          <pose>-2.37907 3.49724 0.775 0 -0 0.544288</pose>
          <velocity>0.000376 0.000212 8e-05 -0.000273 0.000486 4e-06</velocity>
          <acceleration>0.737352 0.449093 0.15961 -0.577417 0.952885 -0.002186</acceleration>
          <wrench>0.737352 0.449093 0.15961 0 -0 0</wrench>
        </link>
        <link name='support_structure'>
          <pose>-2.39073 3.51649 0.025 0 -0 0.544288</pose>
          <velocity>1.2e-05 7e-06 8.2e-05 -0.000278 0.000496 5e-06</velocity>
          <acceleration>0.023276 0.016012 0.163224 -0.588969 0.973084 -0.001319</acceleration>
          <wrench>0.023276 0.016012 0.163224 0 -0 0</wrench>
        </link>
      </model>
      <model name='Turn_Left_signal'>
        <pose>5.40861 3.29812 0.025002 1.7e-05 -0 -1.63054</pose>
        <scale>1 1 1</scale>
        <link name='pictogram'>
          <pose>5.38614 3.29946 0.775001 1.7e-05 -0 -1.63054</pose>
          <velocity>0.000905 -5.4e-05 -9.1e-05 7e-05 0.001168 5e-06</velocity>
          <acceleration>0.514306 -0.030603 -0.051535 0.039666 0.663607 0.009728</acceleration>
          <wrench>0.514306 -0.030603 -0.051535 0 -0 0</wrench>
        </link>
        <link name='support_structure'>
          <pose>5.40861 3.29812 0.025002 1.7e-05 -0 -1.63054</pose>
          <velocity>2.9e-05 -2e-06 -0.000117 7e-05 0.00117 1e-06</velocity>
          <acceleration>0.016587 -0.000847 -0.066422 0.039634 0.663036 0.001402</acceleration>
          <wrench>0.016587 -0.000847 -0.066422 0 -0 0</wrench>
        </link>
      </model>
      <model name='Turn_Left_signal_0'>
        <pose>-5.95143 -1.15058 0.025001 5e-06 -0 -1.58197</pose>
        <scale>1 1 1</scale>
        <link name='pictogram'>
          <pose>-5.97394 -1.15033 0.775 5e-06 -0 -1.58197</pose>
          <velocity>-0.002211 2.5e-05 0.000731 -3.2e-05 -0.002852 0</velocity>
          <acceleration>0.575024 -0.005833 1.17126 0.008248 0.74222 -0.006685</acceleration>
          <wrench>0.575024 -0.005833 1.17126 0 -0 0</wrench>
        </link>
        <link name='support_structure'>
          <pose>-5.95143 -1.15058 0.025001 5e-06 -0 -1.58197</pose>
          <velocity>-7.1e-05 1e-06 0.000807 -3.2e-05 -0.002839 5e-06</velocity>
          <acceleration>0.0188 0.000336 1.16701 0.008432 0.758502 0.003909</acceleration>
          <wrench>0.0188 0.000336 1.16701 0 -0 0</wrench>
        </link>
      </model>
      <model name='fnr2022_map'>
        <pose>-0.033622 1.43805 0 0 -0 0</pose>
        <scale>1 1 1</scale>
        <link name='link'>
          <pose>-0.033622 1.43805 0 0 -0 0</pose>
          <velocity>0 0 0 0 -0 0</velocity>
          <acceleration>0 0 0 0 -0 0</acceleration>
          <wrench>0 0 0 0 -0 0</wrench>
        </link>
      </model>
      <model name='prometheus'>
        <pose>-0.008083 -0.290303 0.059999 0 2e-06 0.235397</pose>
        <scale>1 1 1</scale>
        <link name='base_footprint'>
          <pose>-0.008083 -0.290303 0.059999 0 2e-06 0.235397</pose>
          <velocity>1.8e-05 -7.4e-05 0.000371 0.00141 2.1e-05 -4.3e-05</velocity>
          <acceleration>0.031536 -0.107362 0.46797 -2.48834 0.621398 0.087814</acceleration>
          <wrench>0.063071 -0.214725 0.935939 0 -0 0</wrench>
        </link>
        <link name='front_left_steer_link'>
          <pose>0.178595 -0.425492 0.139999 0 2e-06 0.243693</pose>
          <velocity>1.3e-05 -0.000192 9.6e-05 0.001427 2.5e-05 0.001078</velocity>
          <acceleration>0.094685 -0.400996 -0.382572 -2.59172 0.59552 0.444032</acceleration>
          <wrench>0.047342 -0.200498 -0.191286 0 -0 0</wrench>
        </link>
        <link name='front_left_wheel_link'>
          <pose>0.178595 -0.425492 0.06 2.41805 -3e-06 1.81449</pose>
          <velocity>1.2e-05 -8.5e-05 1.8e-05 0.001344 0.000482 0.001105</velocity>
          <acceleration>0.048373 -0.113146 -0.460462 3.07296 0.91982 1.48459</acceleration>
          <wrench>0.024186 -0.056573 -0.230231 0 -0 0</wrench>
        </link>
        <link name='front_right_steer_link'>
          <pose>0.096965 -0.085144 0.139999 0 2e-06 0.243664</pose>
          <velocity>2.9e-05 -0.000194 0.00076 0.001448 2.8e-05 0.00034</velocity>
          <acceleration>0.063409 -0.401522 1.44496 -2.4664 0.624786 -0.460274</acceleration>
          <wrench>0.031704 -0.200761 0.72248 0 -0 0</wrench>
        </link>
        <link name='front_right_wheel_link'>
          <pose>0.096965 -0.085144 0.06 2.39287 -0 -1.32714</pose>
          <velocity>3.1e-05 -9.2e-05 0.000859 0.001555 0.000451 0.000236</velocity>
          <acceleration>0.017266 -0.11035 1.54417 -2.96026 0.898468 -1.69617</acceleration>
          <wrench>0.008633 -0.055175 0.772083 0 -0 0</wrench>
        </link>
        <link name='front_steer_link'>
          <pose>-0.202567 -0.336948 0.14 -2e-06 -1e-06 -1.85034</pose>
          <velocity>1.7e-05 -0.000175 0.000307 0.001405 1.9e-05 0.019454</velocity>
          <acceleration>0.083519 -0.419818 0.406906 -2.49342 0.620122 -1.3e-05</acceleration>
          <wrench>0.04176 -0.209909 0.203453 0 -0 0</wrench>
        </link>
        <link name='rear_left_wheel_link'>
          <pose>-0.113131 -0.495461 0.06 -0.197288 1e-06 1.8062</pose>
          <velocity>1e-05 -7.5e-05 3.3e-05 0.001251 0.000158 -4.5e-05</velocity>
          <acceleration>0.05076 -0.121965 -0.295879 -2.69692 0.746769 0.411736</acceleration>
          <wrench>0.02538 -0.060982 -0.147939 0 -0 0</wrench>
        </link>
        <link name='rear_right_wheel_link'>
          <pose>-0.194761 -0.155113 0.06 -0.460342 -2e-06 -1.3354</pose>
          <velocity>2.5e-05 -7.3e-05 0.00061 0.001222 0.000426 -3.9e-05</velocity>
          <acceleration>0.02154 -0.13115 1.14175 -3.03132 0.941335 -0.568475</acceleration>
          <wrench>0.01077 -0.065575 0.570873 0 -0 0</wrench>
        </link>
        <link name='rear_wheel_link'>
          <pose>0.186401 -0.243657 0.059999 2.48034 -0 -1.3354</pose>
          <velocity>1.9e-05 -8.1e-05 0.00043 0.257159 -1.06631 -4.1e-05</velocity>
          <acceleration>0.026551 -0.086842 0.517463 3.05795 0.73342 -0.721928</acceleration>
          <wrench>0.013275 -0.043421 0.258732 0 -0 0</wrench>
        </link>
      </model>
      <model name='semaphore_monitor'>
        <pose>-0 -0.044776 0.113553 0 -0 -1.57185</pose>
        <scale>1 1 1</scale>
        <link name='lcd1'>
          <pose>0.000421 0.355224 1.19915 2.0071 -0 1.56965</pose>
          <velocity>0 0 0 0 -0 0</velocity>
          <acceleration>0 0 0 0 -0 0</acceleration>
          <wrench>0 0 0 0 -0 0</wrench>
        </link>
        <link name='lcd2'>
          <pose>-0.000421 -0.444776 1.19915 2.0071 0 -1.57185</pose>
          <velocity>0 0 0 0 -0 0</velocity>
          <acceleration>0 0 0 0 -0 0</acceleration>
          <wrench>0 0 0 0 -0 0</wrench>
        </link>
      </model>
      <light name='sun'>
        <pose>0 0 10 0 -0 0</pose>
      </light>
    </state>
  </world>
</sdf>
