<?xml version="1.0" ?>
<robot name="$(arg player_name)" xmlns:xacro="http://ros.org/wiki/xacro">
<!--<robot name="p_g5" xmlns:xacro="http://ros.org/wiki/xacro">-->
  <xacro:include filename="$(find robot_description)/urdf/common_properties.xacro"/>

  <xacro:property name="player_name" value="$(arg player_name)"  />
  <xacro:property name="player_color" value="$(arg player_color)"  />
  <xacro:property name="base_color" value="$(arg base_color)" />
  <xacro:property name="scan_color" value="$(arg scan_color)" />
   <xacro:property name="orientacao" value="$(arg orientacao)" />

<!--  <xacro:property name="player_name" default="p_g5" />-->
<!--  <xacro:property name="player_color" default="Orange" />-->
<!--  <xacro:property name="base_color" default="DarkGrey"/>-->
<!--  <xacro:property name="scan_color" default="FlatBlack"/>-->


  <xacro:include filename="$(find robot_description)/urdf/robot_final.gazebo.macro.xacro"/>

  <link name="base_footprint"/>

  <joint name="base_joint" type="fixed">
    <parent link="base_footprint"/>
    <child link="base_link" />
    <origin xyz="0 0 0.200" rpy="0 0 0"/>
  </joint>

  <link name="base_link">
    <visual>
      <!-- <origin xyz="-0.064 0 0.0" rpy="0 0 0"/> -->
      <origin xyz="-0.55 -0.175 -0.150" rpy="0 0 0"/>
      <geometry>
        <!-- <mesh filename="package://turtlebot3_description/meshes/bases/waffle_pi_base.stl" scale="0.001 0.001 0.001"/> -->
        <!-- <mesh filename="$(find robot_description)/meshes/base_link.STL" scale="0.001 0.001 0.001"/> -->
        <mesh filename="$(find robot_description)/meshes/CarroSemRodasZ.STL" scale="0.001 0.001 0.001 "/>
        <!-- <mesh filename="$(find robot_description)/meshes/CarroSemRodasZSemKinectics.STL" scale="0.001 0.001 0.001 "/> -->
      </geometry>
      <material name="${player_color}"/>
    </visual>

    <collision>
      <origin xyz="-0.250 0 0.222" rpy="0 0 0"/>
      <geometry>
        <box size="0.600 0.350 0.480"/>
      </geometry>
    </collision>

    <inertial>
      <origin xyz="-0.250 0 0.172" rpy="0 0 0"/>
      <mass value="1.3729096e+00"/>
      <inertia ixx="8.7002718e-03" ixy="-4.7576583e-05" ixz="1.1160499e-04"
               iyy="8.6195418e-03" iyz="-3.5422299e-06"
               izz="1.4612727e-02" />
    </inertial>
  </link>



  <!-- wheel_left_joint -->

  <joint name="wheel_left_joint" type="continuous">
    <parent link="base_link"/>
    <child link="wheel_left_link"/>
    <origin xyz="-0.400 0.1225 -0.1375" rpy="0 0 0"/>
    <axis xyz="0 1 0"/>
  </joint>

  <link name="wheel_left_link">
    <visual>
      <origin xyz="0.0625 0 -0.0625" rpy="0 0 3.14"/>
      <geometry>
        <mesh filename="$(find robot_description)/meshes/RodaPecaCanto.STL" scale="0.001 0.001 0.001"/>
      </geometry>
      <material name="${player_color}"/>
    </visual>

    <collision>
      <origin xyz="0 -0.0215 0" rpy="1.57 0 0"/>
      <geometry>
        <cylinder length="0.045" radius="0.0625"/>
      </geometry>
    </collision>

    <inertial>
      <origin xyz="0 -0.0215 0" rpy="1.57 0 0"/>
      <mass value="0.5" />
      <inertia ixx="1.1175580e-05" ixy="-4.2369783e-11" ixz="-5.9381719e-09"
               iyy="1.1192413e-05" iyz="-1.4400107e-11"
               izz="2.0712558e-05" />
      </inertial>
  </link>



  
<!-- wheel_left_front_joint -->

  <joint name="wheel_left_front_joint" type="continuous">
    <parent link="base_link"/>
    <child link="wheel_left_front_link"/>
    <origin xyz="-0.100 0.1225 -0.1375" rpy="0 0 0"/>
    <axis xyz="0 1 0"/>
  </joint>

  <link name="wheel_left_front_link">
    <visual>
      <origin xyz="0.0625 0 -0.0625" rpy="0 0 3.14"/>
      <geometry>
        <mesh filename="$(find robot_description)/meshes/RodaPecaCanto.STL" scale="0.001 0.001 0.001"/>
      </geometry>
      <material name="${player_color}"/>
    </visual>

    <collision>
      <origin xyz="0 -0.0215 0" rpy="1.57 0 0"/>
      <geometry>
        <cylinder length="0.045" radius="0.0625"/>
      </geometry>
    </collision>

    <inertial>
      <origin xyz="0 -0.0215 0" rpy="1.57 0 0"/>
      <mass value="0.5" />
      <inertia ixx="1.1175580e-05" ixy="-4.2369783e-11" ixz="-5.9381719e-09"
               iyy="1.1192413e-05" iyz="-1.4400107e-11"
               izz="2.0712558e-05" />
      </inertial>
  </link>
  







  <!-- wheel_right_joint -->

  <joint name="wheel_right_joint" type="continuous">
    <parent link="base_link"/>
    <child link="wheel_right_link"/>
    <origin xyz="-0.400 -0.1225 -0.1375" rpy="0 0 0"/>
    <axis xyz="0 1 0"/>
  </joint>

  <link name="wheel_right_link">
    <visual>
      <origin xyz="-0.0625 0 -0.0625" rpy="0 0 0"/>
      <geometry>
        <mesh filename="$(find robot_description)/meshes/RodaPecaCanto.STL" scale="0.001 0.001 0.001"/>
      </geometry>
      <material name="${player_color}"/>
    </visual>

    <collision>
      <origin xyz="0 0.0235 0" rpy="1.57 0 0"/>
      <geometry>
        <cylinder length="0.045" radius="0.0625"/>
      </geometry>
    </collision>

    <inertial>
      <origin xyz="0 0.0235 0" rpy="1.57 0 0"/>
      <mass value="0.5" />
      <inertia ixx="1.1175580e-05" ixy="-4.2369783e-11" ixz="-5.9381719e-09"
               iyy="1.1192413e-05" iyz="-1.4400107e-11"
               izz="2.0712558e-05" />
      </inertial>
  </link>

  
  



  <!-- wheel_right_front_joint -->

 <joint name="wheel_right_front_joint" type="continuous">
    <parent link="base_link"/>
    <child link="wheel_right_front_link"/>
    <origin xyz="-0.100 -0.1225 -0.1375" rpy="0 0 0"/>
    <axis xyz="0 1 0"/>
  </joint>

  <link name="wheel_right_front_link">
    <visual>
      <origin xyz="-0.0625 0 -0.0625" rpy="0 0 0"/>
      <geometry>
        <mesh filename="$(find robot_description)/meshes/RodaPecaCanto.STL" scale="0.001 0.001 0.001"/>
      </geometry>
      <material name="${player_color}"/>
    </visual>

    <collision>
      <origin xyz="0 0.0235 0" rpy="1.57 0 0"/>
      <geometry>
        <cylinder length="0.045" radius="0.0625"/>
      </geometry>
    </collision>

    <inertial>
      <origin xyz="0 0.0235 0" rpy="1.57 0 0"/>
      <mass value="0.5" />
      <inertia ixx="1.1175580e-05" ixy="-4.2369783e-11" ixz="-5.9381719e-09"
               iyy="1.1192413e-05" iyz="-1.4400107e-11"
               izz="2.0712558e-05" />
      </inertial>
  </link>
 



<!-- 
  <joint name="caster_back_right_joint" type="fixed">
    <parent link="base_link"/>
    <child link="caster_back_right_link"/>
    <origin xyz="-0.177 -0.064 -0.004" rpy="-1.57 0 0"/>
  </joint>

  <link name="caster_back_right_link">
    <collision>
      <origin xyz="0 0.001 0" rpy="0 0 0"/>
      <geometry>
        <box size="0.030 0.009 0.020"/>
      </geometry>
    </collision>

    <inertial>
      <origin xyz="0 0 0" />
      <mass value="0.005" />
      <inertia ixx="0.001" ixy="0.0" ixz="0.0"
               iyy="0.001" iyz="0.0"
               izz="0.001" />
    </inertial>
  </link>
 -->





<!-- 
  <joint name="caster_back_left_joint" type="fixed">
    <parent link="base_link"/>
    <child link="caster_back_left_link"/>
    <origin xyz="-0.177 0.064 -0.004" rpy="-1.57 0 0"/>
  </joint>

  <link name="caster_back_left_link">
    <collision>
      <origin xyz="0 0.001 0" rpy="0 0 0"/>
      <geometry>
        <box size="0.030 0.009 0.020"/>
      </geometry>
    </collision>

    <inertial>
      <origin xyz="0 0 0" />
      <mass value="0.005" />
      <inertia ixx="0.001" ixy="0.0" ixz="0.0"
               iyy="0.001" iyz="0.0"
               izz="0.001" />
    </inertial>
  </link>
 -->



<!-- 
  <joint name="imu_joint" type="fixed">
    <parent link="base_link"/>
    <child link="imu_link"/>
    <origin xyz="0.0 0 0.068" rpy="0 0 0"/>
  </joint>

  <link name="imu_link"/> 
-->


<!-- Daniel -->

  <joint name="imu_joint" type="fixed">
    <parent link="base_link"/>
    <child link="imu_link"/>
    <origin xyz="0.0 0 0.068" rpy="0 0 0"/>
  </joint>

  <link name="imu_link"/>
<!-- Daniel End -->




<!-- Scan base sensors -->
  <!-- <joint name="scan_joint" type="fixed">
    <parent link="base_link"/>
    <child link="base_scan"/>
    <origin xyz="0 0 0.0624" rpy="0 0 0"/>
  </joint>

  <link name="base_scan">
    <visual>
      <origin xyz="-0.136 0.0289 -0.025" rpy="1.57 0 0"/>
      <geometry>
        <mesh filename="$(find robot_description)/meshes/Portico_1 - portico2-1.STL" scale="0.001 0.001 0.001"/>
      </geometry>
      <material name="${player_color}"/>
    </visual>

    <collision>
      <origin xyz="0.15 -0.15 0.25" rpy="0 0 0"/>
      <geometry>
        <box size="0.6 0.350 0.425"/>
      </geometry>
    </collision>

    <inertial>
      <mass value="0.114" />
      <origin xyz="0 0 0" />
      <inertia ixx="0.001" ixy="0.0" ixz="0.0"
               iyy="0.001" iyz="0.0"
               izz="0.001" />
    </inertial>
  </link>  -->

<!-- ett -->

  

  <!-- Camera link -->
  <joint name="camera_joint" type="fixed">
    <origin xyz="-0.05 0 0.350" rpy="0 0 0"/>
    <parent link="base_link"/>
    <child link="camera_link"/>
  </joint>

  <link name="camera_link">
   
  </link> 




  <!-- camera_rgb_joint -->
  <joint name="camera_rgb_joint" type="fixed">
    <origin xyz="0 0 0" rpy="0 0 0"/>    
    <parent link="camera_link"/>
    <child link="camera_rgb_frame"/>
  </joint>

  <link name="camera_rgb_frame">
    <visual>
      <origin xyz="0.03 -0.138 -0.05 " rpy="0 0 1.57"/>
      <geometry>
        <mesh filename="$(find robot_description)/meshes/KinectZ.STL" scale="0.001 0.001 0.001"/>
      </geometry>
      <material name="${base_color}"/>
    </visual>

    <collision>
      <origin xyz="0 0 0" rpy="0 0 0"/>
      <geometry>
        <box size="0.1 0.3 0.1"/>
      </geometry>
    </collision>
      </link>




  <!-- camera_rgb_optical_joint -->
  <joint name="camera_rgb_optical_joint" type="fixed">
    <origin xyz="0 0 0" rpy="-1.57 0 -1.57"/>
    <parent link="camera_rgb_frame"/>
    <child link="camera_rgb_optical_frame"/>
  </joint>
  <link name="camera_rgb_optical_frame"/> 



</robot>
